Workbook

Sheet Leia-me
B2: Matriz de Prioridades das Atividades do ClickUp
B3: Projeto Next · Processos · lista "Implantação de Melhorias (5W2H)" · proposta para validação
B5: Para que serve | C5: Dar uma nota de importância a cada atividade aberta do ClickUp e traduzir a nota em 4 categorias: 1 Baixa, 2 Normal, 3 Alta, 4 Urgente. A prioridade que hoje está no ClickUp NÃO foi usada.
B6: A ideia em uma frase | C6: Importância é uma coisa, prazo é outra e esforço é outra. A nota mede só a importância. O esforço e o prazo servem para ordenar as atividades dentro de cada categoria.
B7: Como a nota é calculada | C7: 1) Cada atividade recebe nota de 1 a 5 em 5 critérios (aba Matriz). 2) A média é ponderada pelos pesos da aba Matriz. 3) Multiplica-se pelo fator do processo (aba Processos): um ajuste pequeno, de 0,9 a 1,1. 4) Soma-se o ajuste da natureza da ação (controle sobe, indicador desce). 5) A nota final vira categoria pelos cortes da aba Matriz. 6) Duas regras passam por cima da conta (vetos): risco de fraude nota 5 vira, no mínimo, Alta; atividade que para a obra ou o repasse da CEF vira Urgente.
B8: Como usar a aba Tarefas | C8: 1) Preencha as células amarelas: esforço (H), as 5 notas (I a M) e, se for o caso, "Para obra ou repasse CEF?" (N). 2) As colunas cinza calculam sozinhas: nota, categoria e prioridade. 3) A coluna "Ordem geral" diz o que fazer primeiro: categoria, depois nota, depois menor esforço. 4) Dá para filtrar por processo, responsável, status ou prioridade.
B9: Cores | C9: Texto azul em fundo amarelo = pode editar (pesos, cortes, notas, esforço). Fundo cinza = fórmula, não editar. Fundo azul-escuro = títulos.
B10: O que é proposta minha | C10: Todos os pesos, cortes, ajustes e médias de processo são PROPOSTA para validar. Nenhum veio de dado oficial. As notas das 12 atividades marcadas como "Âncora (proposta)" também são minhas: servem de exemplo e de referência para calibrar. Troque qualquer valor azul e tudo recalcula.
B11: Fonte dos dados | C11: ClickUp, lista "Implantação de Melhorias (5W2H)", lida em 21/10/2026. Entram 401 atividades abertas (status: sem prazo definido, em progresso, em atraso e pausado). Ficam de fora as concluídas e as canceladas. Processo e Tipo de Ação vêm dos campos do ClickUp; onde o campo estava vazio usei a etiqueta; sem nenhum dos dois ficou "Sem processo definido".
B12: Sugestões automáticas | C12: A coluna "Natureza" (Controle, Documento normativo, etc.) é uma sugestão minha a partir do tipo de ação do ClickUp e de palavras do nome da tarefa. Revise e troque pela lista suspensa se estiver errada.
B13: Limites | C13: A planilha não altera nada no ClickUp. As notas dos critérios (colunas I a M) ficam em branco para as áreas e o Processos pontuarem, exceto nas âncoras.

Sheet Matriz
A1: Matriz de critérios, pesos e regras
A2: Células azuis em fundo amarelo podem ser editadas. Pesos e cortes são proposta.
A4: Critério | B4: Pergunta | C4: Peso (%) | D4: Nota 1 | E4: Nota 2 | F4: Nota 3 | G4: Nota 4 | H4: Nota 5
A5: Risco de fraude e erro | B5: Pode haver desvio de dinheiro ou erro grave sem que alguém perceba? | C5: 30 | D5: Nenhum risco relevante. | E5: Erro pequeno e fácil de achar. | F5: Erro ou desvio possível, mas há conferência depois. | G5: Desvio ou erro de valor possível e sem barreira clara. | H5: Dinheiro sai ou dado crítico muda sem trava, aprovação ou conferência.
A6: Impacto financeiro | B6: Quanto dinheiro está em jogo ou pode ser perdido ou ganho? | C6: 20 | D6: Sem efeito em caixa. | E6: Efeito pequeno (exemplo: até R$ 10 mil). | F6: Efeito médio (exemplo: R$ 10 a 50 mil). | G6: Efeito grande (exemplo: R$ 50 a 200 mil). | H6: Efeito muito grande (exemplo: acima de R$ 200 mil). Faixas a confirmar com o Financeiro.
A7: Impacto na obra e na entrega | B7: Atrasa obra, lançamento, repasse ou entrega? | C7: 20 | D7: Nenhum efeito. | E7: Atrasa rotina interna. | F7: Atrasa uma etapa, sem afetar marco. | G7: Pode atrasar marco de obra ou de lançamento. | H7: Para a obra, o repasse da CEF ou a entrega.
A8: Exigência legal, CEF e compliance | B8: Existe lei, norma, contrato, CEF ou LGPD exigindo isso? | C8: 15 | D8: Nenhuma. | E8: Boa prática interna. | F8: Exigência interna formal (política, procedimento). | G8: Exigência de contrato, CEF ou LGPD. | H8: Lei, norma de segurança ou risco de multa ou embargo.
A9: Dependência | B9: Outras atividades ou áreas esperam por esta? | C9: 15 | D9: Ninguém espera. | E9: Uma atividade espera. | F9: Duas ou três atividades, ou uma área. | G9: Várias áreas esperam. | H9: Destrava um processo inteiro ou vários fluxos.
A10: Soma dos pesos | B10: =IF(C10=100,"Soma correta (100%)","ATENÇÃO: os pesos devem somar 100") -> Soma correta (100%) | C10: =SUM(C5:C9) -> 100
A12: Esforço (não entra na nota) | B12: Quanto custa fazer? Só ordena dentro da categoria e marca ganho rápido. | C12: — | D12: Nível 1: Até 1 semana. | E12: Nível 2: Até 1 mês. | F12: Nível 3: Até 3 meses. | G12: Nível 4: Mais de 3 meses. | H12: Nível 5: Depende de contratação, sistema externo ou decisão da diretoria.
A14: Cortes das categorias
A15: Categoria | B15: Significado | C15: Nota mínima (≥)
A16: 1 · Baixa | B16: Pode esperar. Fazer quando houver folga. | C16: 0
A17: 2 · Normal | B17: Entra na rotina de melhoria. | C17: 2.5
A18: 3 · Alta | B18: Planejar para o próximo ciclo. | C18: 3.3
A19: 4 · Urgente | B19: Tratar já, com dono e prazo. | C19: 4
A21: Regras que passam por cima da conta (vetos)
A22: Regra | B22: Quando vale | C22: Categoria mínima
A23: Risco no nível máximo | B23: A nota de "Risco de fraude e erro" é 5. | C23: 3
A24: Para obra ou repasse da CEF | B24: Coluna N da aba Tarefas marcada como "Sim". | C24: 4
A26: Ajuste por natureza da ação (somado à nota)
A27: Natureza | B27: Quando usar | C27: Ajuste
A28: Controle | B28: Alçada, trava, segregação, aprovação, conciliação, acesso. Protege contra fraude e erro. | C28: 0.3
A29: Documento normativo | B29: POP, IT, Política ou Regimento. A nota vem do risco que o documento cobre. | C29: 0
A30: Automação ou sistema | B30: Integração, parametrização, campo, módulo. A nota vem do que protege ou acelera. | C30: 0
A31: Definição ou decisão | B31: Definir regra, responsável ou prazo, ou avaliar uma opção. | C31: 0
A32: Treinamento | B32: Treinar equipe. Sobe a nota pelos critérios quando sustenta um controle. | C32: -0.2
A33: Indicador | B33: Medir sem proteger. Se o indicador detecta desvio (exemplo: avanço físico x financeiro), classificar como Controle. | C33: -0.3
A35: Nota final = média ponderada dos 5 critérios × fator do processo + ajuste da natureza. Depois aplicam-se os vetos. Esforço e prazo só ordenam.

Sheet Processos
A1: Peso dos processos (cadeia de valor)
A2: Três perguntas, de 1 a 5, por processo. O fator é um ajuste pequeno sobre a nota; o risco da atividade manda mais do que o processo.
A4: Fator mínimo | B4: 0.9
A5: Fator máximo | B5: 1.1
A7: Processo | B7: Dinheiro (1–5) | C7: Dependência (1–5) | D7: Irreversibilidade (1–5) | E7: Média | F7: Fator | G7: Por quê (hipótese para validar)
A8: Incorporação Make It | B8: 5 | C8: 5 | D8: 5 | E8: =ROUND(AVERAGE(B8:D8),2) -> 5 | F8: =ROUND($B$4+($B$5-$B$4)*(E8-1)/4,3) -> 1.1 | G8: Define produto, projeto e custo. Quase tudo depende e o erro volta caro.
A9: Incorporação Gadens | B9: 5 | C9: 5 | D9: 5 | E9: =ROUND(AVERAGE(B9:D9),2) -> 5 | F9: =ROUND($B$4+($B$5-$B$4)*(E9-1)/4,3) -> 1.1 | G9: Mesma lógica; ciclo mais longo e valor por unidade maior.
A10: Engenharia | B10: 5 | C10: 5 | D10: 4 | E10: =ROUND(AVERAGE(B10:D10),2) -> 4.67 | F10: =ROUND($B$4+($B$5-$B$4)*(E10-1)/4,3) -> 1.084 | G10: Orçamento, planejamento e obra concentram o maior custo e o caminho crítico.
A11: Novos Negócios | B11: 5 | C11: 3 | D11: 5 | E11: =ROUND(AVERAGE(B11:D11),2) -> 4.33 | F11: =ROUND($B$4+($B$5-$B$4)*(E11-1)/4,3) -> 1.067 | G11: Poucas decisões, mas irreversíveis (compra de terreno, contratos, SPE).
A12: Suprimentos | B12: 5 | C12: 4 | D12: 3 | E12: =ROUND(AVERAGE(B12:D12),2) -> 4 | F12: =ROUND($B$4+($B$5-$B$4)*(E12-1)/4,3) -> 1.05 | G12: Maior parte do custo de obra passa por compras; erro de compra tem correção parcial.
A13: Financeiro | B13: 4 | C13: 5 | D13: 3 | E13: =ROUND(AVERAGE(B13:D13),2) -> 4 | F13: =ROUND($B$4+($B$5-$B$4)*(E13-1)/4,3) -> 1.05 | G13: Todo pagamento e conciliação passa por aqui. É processo de apoio, mas de alto risco.
A14: GMO | B14: 4 | C14: 4 | D14: 3 | E14: =ROUND(AVERAGE(B14:D14),2) -> 3.67 | F14: =ROUND($B$4+($B$5-$B$4)*(E14-1)/4,3) -> 1.034 | G14: Contratos de empreiteiros e medição; a obra depende deles para iniciar e pagar.
A15: Comercial Make It | B15: 4 | C15: 4 | D15: 3 | E15: =ROUND(AVERAGE(B15:D15),2) -> 3.67 | F15: =ROUND($B$4+($B$5-$B$4)*(E15-1)/4,3) -> 1.034 | G15: Caixa depende do ritmo de venda e do repasse da CEF.
A16: Comercial Gadens | B16: 4 | C16: 3 | D16: 3 | E16: =ROUND(AVERAGE(B16:D16),2) -> 3.33 | F16: =ROUND($B$4+($B$5-$B$4)*(E16-1)/4,3) -> 1.017 | G16: Ciclo mais lento e com mais folga que o Make It.
A17: Sem processo definido | B17: 3 | C17: 3 | D17: 3 | E17: =ROUND(AVERAGE(B17:D17),2) -> 3 | F17: =ROUND($B$4+($B$5-$B$4)*(E17-1)/4,3) -> 1 | G17: Atividade sem Processo nem etiqueta no ClickUp. Fator neutro.

Sheet Resumo
A1: Resumo da priorização
A2: Tudo calculado a partir da aba Tarefas.
A4: Atividades abertas | B4: =COUNTA(Tarefas!$A$5:$A$405) -> 401
A5: Já pontuadas | B5: =COUNT(Tarefas!$R$5:$R$405) -> 12
A6: Falta pontuar | B6: =B4-B5 -> 389
A8: Prioridade | B8: Quantidade | C8: % das pontuadas | D8: Meta máxima | E8: Situação
A9: 4 · Urgente | B9: =COUNTIF(Tarefas!$T$5:$T$405,4) -> 2 | C9: =IF($B$5=0,0,B9/$B$5) -> 0.16666667 | D9: 0.1 | E9: =IF($B$5=0,"—",IF(C9>D9,"Acima da meta: revisar cortes","Dentro da meta")) -> Acima da meta: revisar cortes
A10: 3 · Alta | B10: =COUNTIF(Tarefas!$T$5:$T$405,3) -> 6 | C10: =IF($B$5=0,0,B10/$B$5) -> 0.5 | D10: 0.25 | E10: =IF($B$5=0,"—",IF(C10>D10,"Acima da meta: revisar cortes","Dentro da meta")) -> Acima da meta: revisar cortes
A11: 2 · Normal | B11: =COUNTIF(Tarefas!$T$5:$T$405,2) -> 2 | C11: =IF($B$5=0,0,B11/$B$5) -> 0.16666667 | D11: — | E11: —
A12: 1 · Baixa | B12: =COUNTIF(Tarefas!$T$5:$T$405,1) -> 2 | C12: =IF($B$5=0,0,B12/$B$5) -> 0.16666667 | D12: — | E12: —
A13: Meta máxima: se Urgente passar de 10% ou Alta de 25% das pontuadas, a escala perde sentido. É proposta; edite as células azuis.
A15: Processo | B15: Abertas | C15: Pontuadas | D15: Urgente | E15: Alta | F15: Normal | G15: Baixa
A16: Incorporação Make It | B16: =COUNTIF(Tarefas!$C$5:$C$405,A16) -> 16 | C16: =COUNTIFS(Tarefas!$C$5:$C$405,A16,Tarefas!$R$5:$R$405,">0") -> 0 | D16: =COUNTIFS(Tarefas!$C$5:$C$405,$A16,Tarefas!$T$5:$T$405,4) -> 0 | E16: =COUNTIFS(Tarefas!$C$5:$C$405,$A16,Tarefas!$T$5:$T$405,3) -> 0 | F16: =COUNTIFS(Tarefas!$C$5:$C$405,$A16,Tarefas!$T$5:$T$405,2) -> 0 | G16: =COUNTIFS(Tarefas!$C$5:$C$405,$A16,Tarefas!$T$5:$T$405,1) -> 0
A17: Incorporação Gadens | B17: =COUNTIF(Tarefas!$C$5:$C$405,A17) -> 12 | C17: =COUNTIFS(Tarefas!$C$5:$C$405,A17,Tarefas!$R$5:$R$405,">0") -> 0 | D17: =COUNTIFS(Tarefas!$C$5:$C$405,$A17,Tarefas!$T$5:$T$405,4) -> 0 | E17: =COUNTIFS(Tarefas!$C$5:$C$405,$A17,Tarefas!$T$5:$T$405,3) -> 0 | F17: =COUNTIFS(Tarefas!$C$5:$C$405,$A17,Tarefas!$T$5:$T$405,2) -> 0 | G17: =COUNTIFS(Tarefas!$C$5:$C$405,$A17,Tarefas!$T$5:$T$405,1) -> 0
A18: Engenharia | B18: =COUNTIF(Tarefas!$C$5:$C$405,A18) -> 81 | C18: =COUNTIFS(Tarefas!$C$5:$C$405,A18,Tarefas!$R$5:$R$405,">0") -> 2 | D18: =COUNTIFS(Tarefas!$C$5:$C$405,$A18,Tarefas!$T$5:$T$405,4) -> 1 | E18: =COUNTIFS(Tarefas!$C$5:$C$405,$A18,Tarefas!$T$5:$T$405,3) -> 1 | F18: =COUNTIFS(Tarefas!$C$5:$C$405,$A18,Tarefas!$T$5:$T$405,2) -> 0 | G18: =COUNTIFS(Tarefas!$C$5:$C$405,$A18,Tarefas!$T$5:$T$405,1) -> 0
A19: Novos Negócios | B19: =COUNTIF(Tarefas!$C$5:$C$405,A19) -> 30 | C19: =COUNTIFS(Tarefas!$C$5:$C$405,A19,Tarefas!$R$5:$R$405,">0") -> 1 | D19: =COUNTIFS(Tarefas!$C$5:$C$405,$A19,Tarefas!$T$5:$T$405,4) -> 1 | E19: =COUNTIFS(Tarefas!$C$5:$C$405,$A19,Tarefas!$T$5:$T$405,3) -> 0 | F19: =COUNTIFS(Tarefas!$C$5:$C$405,$A19,Tarefas!$T$5:$T$405,2) -> 0 | G19: =COUNTIFS(Tarefas!$C$5:$C$405,$A19,Tarefas!$T$5:$T$405,1) -> 0
A20: Suprimentos | B20: =COUNTIF(Tarefas!$C$5:$C$405,A20) -> 35 | C20: =COUNTIFS(Tarefas!$C$5:$C$405,A20,Tarefas!$R$5:$R$405,">0") -> 2 | D20: =COUNTIFS(Tarefas!$C$5:$C$405,$A20,Tarefas!$T$5:$T$405,4) -> 0 | E20: =COUNTIFS(Tarefas!$C$5:$C$405,$A20,Tarefas!$T$5:$T$405,3) -> 1 | F20: =COUNTIFS(Tarefas!$C$5:$C$405,$A20,Tarefas!$T$5:$T$405,2) -> 1 | G20: =COUNTIFS(Tarefas!$C$5:$C$405,$A20,Tarefas!$T$5:$T$405,1) -> 0
A21: Financeiro | B21: =COUNTIF(Tarefas!$C$5:$C$405,A21) -> 44 | C21: =COUNTIFS(Tarefas!$C$5:$C$405,A21,Tarefas!$R$5:$R$405,">0") -> 4 | D21: =COUNTIFS(Tarefas!$C$5:$C$405,$A21,Tarefas!$T$5:$T$405,4) -> 0 | E21: =COUNTIFS(Tarefas!$C$5:$C$405,$A21,Tarefas!$T$5:$T$405,3) -> 3 | F21: =COUNTIFS(Tarefas!$C$5:$C$405,$A21,Tarefas!$T$5:$T$405,2) -> 0 | G21: =COUNTIFS(Tarefas!$C$5:$C$405,$A21,Tarefas!$T$5:$T$405,1) -> 1
A22: GMO | B22: =COUNTIF(Tarefas!$C$5:$C$405,A22) -> 75 | C22: =COUNTIFS(Tarefas!$C$5:$C$405,A22,Tarefas!$R$5:$R$405,">0") -> 0 | D22: =COUNTIFS(Tarefas!$C$5:$C$405,$A22,Tarefas!$T$5:$T$405,4) -> 0 | E22: =COUNTIFS(Tarefas!$C$5:$C$405,$A22,Tarefas!$T$5:$T$405,3) -> 0 | F22: =COUNTIFS(Tarefas!$C$5:$C$405,$A22,Tarefas!$T$5:$T$405,2) -> 0 | G22: =COUNTIFS(Tarefas!$C$5:$C$405,$A22,Tarefas!$T$5:$T$405,1) -> 0
A23: Comercial Make It | B23: =COUNTIF(Tarefas!$C$5:$C$405,A23) -> 47 | C23: =COUNTIFS(Tarefas!$C$5:$C$405,A23,Tarefas!$R$5:$R$405,">0") -> 0 | D23: =COUNTIFS(Tarefas!$C$5:$C$405,$A23,Tarefas!$T$5:$T$405,4) -> 0 | E23: =COUNTIFS(Tarefas!$C$5:$C$405,$A23,Tarefas!$T$5:$T$405,3) -> 0 | F23: =COUNTIFS(Tarefas!$C$5:$C$405,$A23,Tarefas!$T$5:$T$405,2) -> 0 | G23: =COUNTIFS(Tarefas!$C$5:$C$405,$A23,Tarefas!$T$5:$T$405,1) -> 0
A24: Comercial Gadens | B24: =COUNTIF(Tarefas!$C$5:$C$405,A24) -> 60 | C24: =COUNTIFS(Tarefas!$C$5:$C$405,A24,Tarefas!$R$5:$R$405,">0") -> 3 | D24: =COUNTIFS(Tarefas!$C$5:$C$405,$A24,Tarefas!$T$5:$T$405,4) -> 0 | E24: =COUNTIFS(Tarefas!$C$5:$C$405,$A24,Tarefas!$T$5:$T$405,3) -> 1 | F24: =COUNTIFS(Tarefas!$C$5:$C$405,$A24,Tarefas!$T$5:$T$405,2) -> 1 | G24: =COUNTIFS(Tarefas!$C$5:$C$405,$A24,Tarefas!$T$5:$T$405,1) -> 1
A25: Sem processo definido | B25: =COUNTIF(Tarefas!$C$5:$C$405,A25) -> 1 | C25: =COUNTIFS(Tarefas!$C$5:$C$405,A25,Tarefas!$R$5:$R$405,">0") -> 0 | D25: =COUNTIFS(Tarefas!$C$5:$C$405,$A25,Tarefas!$T$5:$T$405,4) -> 0 | E25: =COUNTIFS(Tarefas!$C$5:$C$405,$A25,Tarefas!$T$5:$T$405,3) -> 0 | F25: =COUNTIFS(Tarefas!$C$5:$C$405,$A25,Tarefas!$T$5:$T$405,2) -> 0 | G25: =COUNTIFS(Tarefas!$C$5:$C$405,$A25,Tarefas!$T$5:$T$405,1) -> 0
A26: Total | B26: =SUM(B16:B25) -> 401 | C26: =SUM(C16:C25) -> 12 | D26: =SUM(D16:D25) -> 2 | E26: =SUM(E16:E25) -> 6 | F26: =SUM(F16:F25) -> 2 | G26: =SUM(G16:G25) -> 2

Sheet Tarefas
A1: Atividades abertas do ClickUp com a matriz
A2: Preencha as células amarelas (H a N). Colunas cinza calculam sozinhas. Âncoras: 12 atividades já pontuadas como proposta, para calibrar.
A4: ID | B4: Tarefa | C4: Processo | D4: Responsável | E4: Status | F4: Prazo | G4: Natureza | H4: Esforço (1–5) | I4: Risco de fraude e erro | J4: Impacto financeiro | K4: Obra e entrega | L4: Legal, CEF e compliance | M4: Dependência | N4: Para obra ou repasse CEF? | O4: Média ponderada | P4: Fator do processo | Q4: Ajuste da natureza | R4: Nota final | S4: Categoria pela nota | T4: Categoria final | U4: Prioridade | V4: Chave | W4: Ordem geral | X4: Origem da nota | Y4: Por que (âncora) | Z4: Calibração
A5: 17tpepcgqnk | B5: Avaliar análise de crédito complementar na modalidade associativo | C5: Comercial Gadens | D5: Érica Ferreira Tavares Silva Caldeira, Cleverton Parnoff | E5: em progresso | F5: 46387 | G5: Definição ou decisão | O5: =IF(COUNT(I5:M5)<5,"",ROUND((I5*Matriz!$C$5+J5*Matriz!$C$6+K5*Matriz!$C$7+L5*Matriz!$C$8+M5*Matriz!$C$9)/SUM(Matriz!$C$5:$C$9),2)) | P5: =IFERROR(INDEX(Processos!$F$8:$F$17,MATCH(C5,Processos!$A$8:$A$17,0)),1) -> 1.017 | Q5: =IFERROR(INDEX(Matriz!$C$28:$C$33,MATCH(G5,Matriz!$A$28:$A$33,0)),0) -> 0 | R5: =IF(O5="","",ROUND(O5*P5+Q5,2)) | S5: =IF(R5="","",IF(R5>=Matriz!$C$19,4,IF(R5>=Matriz!$C$18,3,IF(R5>=Matriz!$C$17,2,1)))) | T5: =IF(S5="","",MAX(S5,IF(I5=5,Matriz!$C$23,0),IF(N5="Sim",Matriz!$C$24,0))) | U5: =IF(T5="","",CHOOSE(T5,"Baixa","Normal","Alta","Urgente")) | V5: =IF(T5="","",T5*1000+R5*10-IF(H5="",3,H5)/10-ROW()/1000000) | W5: =IF(V5="","",COUNTIF($V$5:$V$405,">"&V5)+1)
A6: 17tpepcgqnn | B6: Avaliar análise de crédito complementar na modalidade bancário | C6: Comercial Gadens | D6: Érica Ferreira Tavares Silva Caldeira, Cleverton Parnoff | E6: em progresso | F6: 46387 | G6: Definição ou decisão | O6: =IF(COUNT(I6:M6)<5,"",ROUND((I6*Matriz!$C$5+J6*Matriz!$C$6+K6*Matriz!$C$7+L6*Matriz!$C$8+M6*Matriz!$C$9)/SUM(Matriz!$C$5:$C$9),2)) | P6: =IFERROR(INDEX(Processos!$F$8:$F$17,MATCH(C6,Processos!$A$8:$A$17,0)),1) -> 1.017 | Q6: =IFERROR(INDEX(Matriz!$C$28:$C$33,MATCH(G6,Matriz!$A$28:$A$33,0)),0) -> 0 | R6: =IF(O6="","",ROUND(O6*P6+Q6,2)) | S6: =IF(R6="","",IF(R6>=Matriz!$C$19,4,IF(R6>=Matriz!$C$18,3,IF(R6>=Matriz!$C$17,2,1)))) | T6: =IF(S6="","",MAX(S6,IF(I6=5,Matriz!$C$23,0),IF(N6="Sim",Matriz!$C$24,0))) | U6: =IF(T6="","",CHOOSE(T6,"Baixa","Normal","Alta","Urgente")) | V6: =IF(T6="","",T6*1000+R6*10-IF(H6="",3,H6)/10-ROW()/1000000) | W6: =IF(V6="","",COUNTIF($V$5:$V$405,">"&V6)+1)
A7: 17tpepcdam9 | B7: Conceder acesso aos sistemas SPC e Serasa | C7: Comercial Gadens | D7: Cleverton Parnoff | E7: em progresso | F7: 46326 | G7: Controle | O7: =IF(COUNT(I7:M7)<5,"",ROUND((I7*Matriz!$C$5+J7*Matriz!$C$6+K7*Matriz!$C$7+L7*Matriz!$C$8+M7*Matriz!$C$9)/SUM(Matriz!$C$5:$C$9),2)) | P7: =IFERROR(INDEX(Processos!$F$8:$F$17,MATCH(C7,Processos!$A$8:$A$17,0)),1) -> 1.017 | Q7: =IFERROR(INDEX(Matriz!$C$28:$C$33,MATCH(G7,Matriz!$A$28:$A$33,0)),0) -> 0.3 | R7: =IF(O7="","",ROUND(O7*P7+Q7,2)) | S7: =IF(R7="","",IF(R7>=Matriz!$C$19,4,IF(R7>=Matriz!$C$18,3,IF(R7>=Matriz!$C$17,2,1)))) | T7: =IF(S7="","",MAX(S7,IF(I7=5,Matriz!$C$23,0),IF(N7="Sim",Matriz!$C$24,0))) | U7: =IF(T7="","",CHOOSE(T7,"Baixa","Normal","Alta","Urgente")) | V7: =IF(T7="","",T7*1000+R7*10-IF(H7="",3,H7)/10-ROW()/1000000) | W7: =IF(V7="","",COUNTIF($V$5:$V$405,">"&V7)+1)
A8: 17tpepcdg1y | B8: Definir periodicidade de limpeza das unidades de estoque vazias - Monica; | C8: Comercial Gadens | D8: Mônica Massaneiro | E8: em progresso | F8: 46326 | G8: Definição ou decisão | O8: =IF(COUNT(I8:M8)<5,"",ROUND((I8*Matriz!$C$5+J8*Matriz!$C$6+K8*Matriz!$C$7+L8*Matriz!$C$8+M8*Matriz!$C$9)/SUM(Matriz!$C$5:$C$9),2)) | P8: =IFERROR(INDEX(Processos!$F$8:$F$17,MATCH(C8,Processos!$A$8:$A$17,0)),1) -> 1.017 | Q8: =IFERROR(INDEX(Matriz!$C$28:$C$33,MATCH(G8,Matriz!$A$28:$A$33,0)),0) -> 0 | R8: =IF(O8="","",ROUND(O8*P8+Q8,2)) | S8: =IF(R8="","",IF(R8>=Matriz!$C$19,4,IF(R8>=Matriz!$C$18,3,IF(R8>=Matriz!$C$17,2,1)))) | T8: =IF(S8="","",MAX(S8,IF(I8=5,Matriz!$C$23,0),IF(N8="Sim",Matriz!$C$24,0))) | U8: =IF(T8="","",CHOOSE(T8,"Baixa","Normal","Alta","Urgente")) | V8: =IF(T8="","",T8*1000+R8*10-IF(H8="",3,H8)/10-ROW()/1000000) | W8: =IF(V8="","",COUNTIF($V$5:$V$405,">"&V8)+1)
A9: 17tpepcdk0j | B9: Definição de alçada de aprovação das vendas | C9: Comercial Gadens | D9: Mônica Massaneiro | E9: em progresso | F9: 46356 | G9: Controle | O9: =IF(COUNT(I9:M9)<5,"",ROUND((I9*Matriz!$C$5+J9*Matriz!$C$6+K9*Matriz!$C$7+L9*Matriz!$C$8+M9*Matriz!$C$9)/SUM(Matriz!$C$5:$C$9),2)) | P9: =IFERROR(INDEX(Processos!$F$8:$F$17,MATCH(C9,Processos!$A$8:$A$17,0)),1) -> 1.017 | Q9: =IFERROR(INDEX(Matriz!$C$28:$C$33,MATCH(G9,Matriz!$A$28:$A$33,0)),0) -> 0.3 | R9: =IF(O9="","",ROUND(O9*P9+Q9,2)) | S9: =IF(R9="","",IF(R9>=Matriz!$C$19,4,IF(R9>=Matriz!$C$18,3,IF(R9>=Matriz!$C$17,2,1)))) | T9: =IF(S9="","",MAX(S9,IF(I9=5,Matriz!$C$23,0),IF(N9="Sim",Matriz!$C$24,0))) | U9: =IF(T9="","",CHOOSE(T9,"Baixa","Normal","Alta","Urgente")) | V9: =IF(T9="","",T9*1000+R9*10-IF(H9="",3,H9)/10-ROW()/1000000) | W9: =IF(V9="","",COUNTIF($V$5:$V$405,">"&V9)+1)
A10: 17tpepcgq44 | B10: Elaborar Fluxo - Tapumes | C10: Comercial Gadens | D10: Andrei Souza Santos | E10: em progresso | F10: 46387 | G10: Definição ou decisão | O10: =IF(COUNT(I10:M10)<5,"",ROUND((I10*Matriz!$C$5+J10*Matriz!$C$6+K10*Matriz!$C$7+L10*Matriz!$C$8+M10*Matriz!$C$9)/SUM(Matriz!$C$5:$C$9),2)) | P10: =IFERROR(INDEX(Processos!$F$8:$F$17,MATCH(C10,Processos!$A$8:$A$17,0)),1) -> 1.017 | Q10: =IFERROR(INDEX(Matriz!$C$28:$C$33,MATCH(G10,Matriz!$A$28:$A$33,0)),0) -> 0 | R10: =IF(O10="","",ROUND(O10*P10+Q10,2)) | S10: =IF(R10="","",IF(R10>=Matriz!$C$19,4,IF(R10>=Matriz!$C$18,3,IF(R10>=Matriz!$C$17,2,1)))) | T10: =IF(S10="","",MAX(S10,IF(I10=5,Matriz!$C$23,0),IF(N10="Sim",Matriz!$C$24,0))) | U10: =IF(T10="","",CHOOSE(T10,"Baixa","Normal","Alta","Urgente")) | V10: =IF(T10="","",T10*1000+R10*10-IF(H10="",3,H10)/10-ROW()/1000000) | W10: =IF(V10="","",COUNTIF($V$5:$V$405,">"&V10)+1)
A11: 17tpepcdg1u | B11: Elaborar POP - Decorados (Incluindo vistoria de decorados) - Mariane; | C11: Comercial Gadens | D11: Mariane Cristine Machado Scandelari | E11: em progresso | F11: 46356 | G11: Documento normativo | O11: =IF(COUNT(I11:M11)<5,"",ROUND((I11*Matriz!$C$5+J11*Matriz!$C$6+K11*Matriz!$C$7+L11*Matriz!$C$8+M11*Matriz!$C$9)/SUM(Matriz!$C$5:$C$9),2)) | P11: =IFERROR(INDEX(Processos!$F$8:$F$17,MATCH(C11,Processos!$A$8:$A$17,0)),1) -> 1.017 | Q11: =IFERROR(INDEX(Matriz!$C$28:$C$33,MATCH(G11,Matriz!$A$28:$A$33,0)),0) -> 0 | R11: =IF(O11="","",ROUND(O11*P11+Q11,2)) | S11: =IF(R11="","",IF(R11>=Matriz!$C$19,4,IF(R11>=Matriz!$C$18,3,IF(R11>=Matriz!$C$17,2,1)))) | T11: =IF(S11="","",MAX(S11,IF(I11=5,Matriz!$C$23,0),IF(N11="Sim",Matriz!$C$24,0))) | U11: =IF(T11="","",CHOOSE(T11,"Baixa","Normal","Alta","Urgente")) | V11: =IF(T11="","",T11*1000+R11*10-IF(H11="",3,H11)/10-ROW()/1000000) | W11: =IF(V11="","",COUNTIF($V$5:$V$405,">"&V11)+1)
A12: 17tpepcgphn | B12: Elaborar POP - Definição de Tabela de Preço | C12: Comercial Gadens | D12: Mônica Massaneiro | E12: em progresso | F12: 46356 | G12: Documento normativo | O12: =IF(COUNT(I12:M12)<5,"",ROUND((I12*Matriz!$C$5+J12*Matriz!$C$6+K12*Matriz!$C$7+L12*Matriz!$C$8+M12*Matriz!$C$9)/SUM(Matriz!$C$5:$C$9),2)) | P12: =IFERROR(INDEX(Processos!$F$8:$F$17,MATCH(C12,Processos!$A$8:$A$17,0)),1) -> 1.017 | Q12: =IFERROR(INDEX(Matriz!$C$28:$C$33,MATCH(G12,Matriz!$A$28:$A$33,0)),0) -> 0 | R12: =IF(O12="","",ROUND(O12*P12+Q12,2)) | S12: =IF(R12="","",IF(R12>=Matriz!$C$19,4,IF(R12>=Matriz!$C$18,3,IF(R12>=Matriz!$C$17,2,1)))) | T12: =IF(S12="","",MAX(S12,IF(I12=5,Matriz!$C$23,0),IF(N12="Sim",Matriz!$C$24,0))) | U12: =IF(T12="","",CHOOSE(T12,"Baixa","Normal","Alta","Urgente")) | V12: =IF(T12="","",T12*1000+R12*10-IF(H12="",3,H12)/10-ROW()/1000000) | W12: =IF(V12="","",COUNTIF($V$5:$V$405,">"&V12)+1)
A13: 17tpepcdk0k | B13: Elaborar POP - Seleção de Imobiliárias (nível A, B e C) | C13: Comercial Gadens | D13: Mônica Massaneiro | E13: em progresso | F13: 46356 | G13: Documento normativo | O13: =IF(COUNT(I13:M13)<5,"",ROUND((I13*Matriz!$C$5+J13*Matriz!$C$6+K13*Matriz!$C$7+L13*Matriz!$C$8+M13*Matriz!$C$9)/SUM(Matriz!$C$5:$C$9),2)) | P13: =IFERROR(INDEX(Processos!$F$8:$F$17,MATCH(C13,Processos!$A$8:$A$17,0)),1) -> 1.017 | Q13: =IFERROR(INDEX(Matriz!$C$28:$C$33,MATCH(G13,Matriz!$A$28:$A$33,0)),0) -> 0 | R13: =IF(O13="","",ROUND(O13*P13+Q13,2)) | S13: =IF(R13="","",IF(R13>=Matriz!$C$19,4,IF(R13>=Matriz!$C$18,3,IF(R13>=Matriz!$C$17,2,1)))) | T13: =IF(S13="","",MAX(S13,IF(I13=5,Matriz!$C$23,0),IF(N13="Sim",Matriz!$C$24,0))) | U13: =IF(T13="","",CHOOSE(T13,"Baixa","Normal","Alta","Urgente")) | V13: =IF(T13="","",T13*1000+R13*10-IF(H13="",3,H13)/10-ROW()/1000000) | W13: =IF(V13="","",COUNTIF($V$5:$V$405,">"&V13)+1)
A14: 17tpepcdama | B14: Elaborar POP ou Política - Premissas Validação da Análise de Crédito - Gadens | C14: Comercial Gadens | D14: Cleverton Parnoff | E14: em progresso | F14: 46387 | G14: Documento normativo | O14: =IF(COUNT(I14:M14)<5,"",ROUND((I14*Matriz!$C$5+J14*Matriz!$C$6+K14*Matriz!$C$7+L14*Matriz!$C$8+M14*Matriz!$C$9)/SUM(Matriz!$C$5:$C$9),2)) | P14: =IFERROR(INDEX(Processos!$F$8:$F$17,MATCH(C14,Processos!$A$8:$A$17,0)),1) -> 1.017 | Q14: =IFERROR(INDEX(Matriz!$C$28:$C$33,MATCH(G14,Matriz!$A$28:$A$33,0)),0) -> 0 | R14: =IF(O14="","",ROUND(O14*P14+Q14,2)) | S14: =IF(R14="","",IF(R14>=Matriz!$C$19,4,IF(R14>=Matriz!$C$18,3,IF(R14>=Matriz!$C$17,2,1)))) | T14: =IF(S14="","",MAX(S14,IF(I14=5,Matriz!$C$23,0),IF(N14="Sim",Matriz!$C$24,0))) | U14: =IF(T14="","",CHOOSE(T14,"Baixa","Normal","Alta","Urgente")) | V14: =IF(T14="","",T14*1000+R14*10-IF(H14="",3,H14)/10-ROW()/1000000) | W14: =IF(V14="","",COUNTIF($V$5:$V$405,">"&V14)+1)
A15: 17tpepcgphp | B15: Elaborar Política - Política Comercial do Empreendimento (Prazo, Condição de Pagamento, Riscos, modalidade e fonte de recurso, campanhas por empreendimento, etc.), depois, elaborar POP | C15: Comercial Gadens | D15: Mônica Massaneiro | E15: em progresso | F15: 46446 | G15: Documento normativo | O15: =IF(COUNT(I15:M15)<5,"",ROUND((I15*Matriz!$C$5+J15*Matriz!$C$6+K15*Matriz!$C$7+L15*Matriz!$C$8+M15*Matriz!$C$9)/SUM(Matriz!$C$5:$C$9),2)) | P15: =IFERROR(INDEX(Processos!$F$8:$F$17,MATCH(C15,Processos!$A$8:$A$17,0)),1) -> 1.017 | Q15: =IFERROR(INDEX(Matriz!$C$28:$C$33,MATCH(G15,Matriz!$A$28:$A$33,0)),0) -> 0 | R15: =IF(O15="","",ROUND(O15*P15+Q15,2)) | S15: =IF(R15="","",IF(R15>=Matriz!$C$19,4,IF(R15>=Matriz!$C$18,3,IF(R15>=Matriz!$C$17,2,1)))) | T15: =IF(S15="","",MAX(S15,IF(I15=5,Matriz!$C$23,0),IF(N15="Sim",Matriz!$C$24,0))) | U15: =IF(T15="","",CHOOSE(T15,"Baixa","Normal","Alta","Urgente")) | V15: =IF(T15="","",T15*1000+R15*10-IF(H15="",3,H15)/10-ROW()/1000000) | W15: =IF(V15="","",COUNTIF($V$5:$V$405,">"&V15)+1)
A16: 17tpepcep33 | B16: Implantar formalização de contratação com as imobiliárias selecionadas/Correspondentes (Contrato de Parceiria - Foco LGPD) | C16: Comercial Gadens | D16: Edgard Machado Ferreira Junior | E16: em progresso | F16: 46387 | G16: Definição ou decisão | O16: =IF(COUNT(I16:M16)<5,"",ROUND((I16*Matriz!$C$5+J16*Matriz!$C$6+K16*Matriz!$C$7+L16*Matriz!$C$8+M16*Matriz!$C$9)/SUM(Matriz!$C$5:$C$9),2)) | P16: =IFERROR(INDEX(Processos!$F$8:$F$17,MATCH(C16,Processos!$A$8:$A$17,0)),1) -> 1.017 | Q16: =IFERROR(INDEX(Matriz!$C$28:$C$33,MATCH(G16,Matriz!$A$28:$A$33,0)),0) -> 0 | R16: =IF(O16="","",ROUND(O16*P16+Q16,2)) | S16: =IF(R16="","",IF(R16>=Matriz!$C$19,4,IF(R16>=Matriz!$C$18,3,IF(R16>=Matriz!$C$17,2,1)))) | T16: =IF(S16="","",MAX(S16,IF(I16=5,Matriz!$C$23,0),IF(N16="Sim",Matriz!$C$24,0))) | U16: =IF(T16="","",CHOOSE(T16,"Baixa","Normal","Alta","Urgente")) | V16: =IF(T16="","",T16*1000+R16*10-IF(H16="",3,H16)/10-ROW()/1000000) | W16: =IF(V16="","",COUNTIF($V$5:$V$405,">"&V16)+1)
... A20: 17tpepcdg1v | B20: Vistoriar todas as unidades de estoque - Alessandro com apoio da AT, Comercial e Incorporação | C20: Comercial Gadens | D20: Alessandro Braz | E20: em progresso | F20: 46356 | G20: Definição ou decisão | O20: =IF(COUNT(I20:M20)<5,"",ROUND((I20*Matriz!$C$5+J20*Matriz!$C$6+K20*Matriz!$C$7+L20*Matriz!$C$8+M20*Matriz!$C$9)/SUM(Matriz!$C$5:$C$9),2)) | P20: =IFERROR(INDEX(Processos!$F$8:$F$17,MATCH(C20,Processos!$A$8:$A$17,0)),1) -> 1.017 | Q20: =IFERROR(INDEX(Matriz!$C$28:$C$33,MATCH(G20,Matriz!$A$28:$A$33,0)),0) -> 0 | R20: =IF(O20="","",ROUND(O20*P20+Q20,2)) | S20: =IF(R20="","",IF(R20>=Matriz!$C$19,4,IF(R20>=Matriz!$C$18,3,IF(R20>=Matriz!$C$17,2,1)))) | T20: =IF(S20="","",MAX(S20,IF(I20=5,Matriz!$C$23,0),IF(N20="Sim",Matriz!$C$24,0))) | U20: =IF(T20="","",CHOOSE(T20,"Baixa","Normal","Alta","Urgente")) | V20: =IF(T20="","",T20*1000+R20*10-IF(H20="",3,H20)/10-ROW()/1000000) | W20: =IF(V20="","",COUNTIF($V$5:$V$405,">"&V20)+1)
A21: 17tpepcpr2a | B21: Adequar fluxo do ClickUp de abertura de SPEs para incluir quais estão disponíveis para NN | C21: Comercial Gadens | D21: Edgard Machado Ferreira Junior | E21: sem prazo definido | G21: Definição ou decisão | O21: =IF(COUNT(I21:M21)<5,"",ROUND((I21*Matriz!$C$5+J21*Matriz!$C$6+K21*Matriz!$C$7+L21*Matriz!$C$8+M21*Matriz!$C$9)/SUM(Matriz!$C$5:$C$9),2)) | P21: =IFERROR(INDEX(Processos!$F$8:$F$17,MATCH(C21,Processos!$A$8:$A$17,0)),1) -> 1.017 | Q21: =IFERROR(INDEX(Matriz!$C$28:$C$33,MATCH(G21,Matriz!$A$28:$A$33,0)),0) -> 0 | R21: =IF(O21="","",ROUND(O21*P21+Q21,2)) | S21: =IF(R21="","",IF(R21>=Matriz!$C$19,4,IF(R21>=Matriz!$C$18,3,IF(R21>=Matriz!$C$17,2,1)))) | T21: =IF(S21="","",MAX(S21,IF(I21=5,Matriz!$C$23,0),IF(N21="Sim",Matriz!$C$24,0))) | U21: =IF(T21="","",CHOOSE(T21,"Baixa","Normal","Alta","Urgente")) | V21: =IF(T21="","",T21*1000+R21*10-IF(H21="",3,H21)/10-ROW()/1000000) | W21: =IF(V21="","",COUNTIF($V$5:$V$405,">"&V21)+1)
A22: 17tpepcgkn9 | B22: Automatizar baixa da reserva no CV | C22: Comercial Gadens | D22: Alexandre Marchiori Cruz | E22: sem prazo definido | G22: Automação ou sistema | O22: =IF(COUNT(I22:M22)<5,"",ROUND((I22*Matriz!$C$5+J22*Matriz!$C$6+K22*Matriz!$C$7+L22*Matriz!$C$8+M22*Matriz!$C$9)/SUM(Matriz!$C$5:$C$9),2)) | P22: =IFERROR(INDEX(Processos!$F$8:$F$17,MATCH(C22,Processos!$A$8:$A$17,0)),1) -> 1.017 | Q22: =IFERROR(INDEX(Matriz!$C$28:$C$33,MATCH(G22,Matriz!$A$28:$A$33,0)),0) -> 0 | R22: =IF(O22="","",ROUND(O22*P22+Q22,2)) | S22: =IF(R22="","",IF(R22>=Matriz!$C$19,4,IF(R22>=Matriz!$C$18,3,IF(R22>=Matriz!$C$17,2,1)))) | T22: =IF(S22="","",MAX(S22,IF(I22=5,Matriz!$C$23,0),IF(N22="Sim",Matriz!$C$24,0))) | U22: =IF(T22="","",CHOOSE(T22,"Baixa","Normal","Alta","Urgente")) | V22: =IF(T22="","",T22*1000+R22*10-IF(H22="",3,H22)/10-ROW()/1000000) | W22: =IF(V22="","",COUNTIF($V$5:$V$405,">"&V22)+1)
A23: 17tpepcgkmw | B23: Automatizar data da venda e competência do contrato | C23: Comercial Gadens | D23: Alexandre Marchiori Cruz | E23: sem prazo definido | G23: Automação ou sistema | O23: =IF(COUNT(I23:M23)<5,"",ROUND((I23*Matriz!$C$5+J23*Matriz!$C$6+K23*Matriz!$C$7+L23*Matriz!$C$8+M23*Matriz!$C$9)/SUM(Matriz!$C$5:$C$9),2)) | P23: =IFERROR(INDEX(Processos!$F$8:$F$17,MATCH(C23,Processos!$A$8:$A$17,0)),1) -> 1.017 | Q23: =IFERROR(INDEX(Matriz!$C$28:$C$33,MATCH(G23,Matriz!$A$28:$A$33,0)),0) -> 0 | R23: =IF(O23="","",ROUND(O23*P23+Q23,2)) | S23: =IF(R23="","",IF(R23>=Matriz!$C$19,4,IF(R23>=Matriz!$C$18,3,IF(R23>=Matriz!$C$17,2,1)))) | T23: =IF(S23="","",MAX(S23,IF(I23=5,Matriz!$C$23,0),IF(N23="Sim",Matriz!$C$24,0))) | U23: =IF(T23="","",CHOOSE(T23,"Baixa","Normal","Alta","Urgente")) | V23: =IF(T23="","",T23*1000+R23*10-IF(H23="",3,H23)/10-ROW()/1000000) | W23: =IF(V23="","",COUNTIF($V$5:$V$405,">"&V23)+1)
A24: 17tpepcpr27 | B24: Automatizar informação de decisão de opção de planta escolhida pelo cliente, via CV, para Planejamento e Controle | C24: Comercial Gadens | D24: Alexandre Marchiori Cruz | E24: sem prazo definido | G24: Automação ou sistema | O24: =IF(COUNT(I24:M24)<5,"",ROUND((I24*Matriz!$C$5+J24*Matriz!$C$6+K24*Matriz!$C$7+L24*Matriz!$C$8+M24*Matriz!$C$9)/SUM(Matriz!$C$5:$C$9),2)) | P24: =IFERROR(INDEX(Processos!$F$8:$F$17,MATCH(C24,Processos!$A$8:$A$17,0)),1) -> 1.017 | Q24: =IFERROR(INDEX(Matriz!$C$28:$C$33,MATCH(G24,Matriz!$A$28:$A$33,0)),0) -> 0 | R24: =IF(O24="","",ROUND(O24*P24+Q24,2)) | S24: =IF(R24="","",IF(R24>=Matriz!$C$19,4,IF(R24>=Matriz!$C$18,3,IF(R24>=Matriz!$C$17,2,1)))) | T24: =IF(S24="","",MAX(S24,IF(I24=5,Matriz!$C$23,0),IF(N24="Sim",Matriz!$C$24,0))) | U24: =IF(T24="","",CHOOSE(T24,"Baixa","Normal","Alta","Urgente")) | V24: =IF(T24="","",T24*1000+R24*10-IF(H24="",3,H24)/10-ROW()/1000000) | W24: =IF(V24="","",COUNTIF($V$5:$V$405,">"&V24)+1)
A25: 17tpepcdm2z | B25: Automatizar processo de contratação com imobiliárias selecionadas | C25: Comercial Gadens | D25: Alexandre Marchiori Cruz | E25: sem prazo definido | G25: Automação ou sistema | O25: =IF(COUNT(I25:M25)<5,"",ROUND((I25*Matriz!$C$5+J25*Matriz!$C$6+K25*Matriz!$C$7+L25*Matriz!$C$8+M25*Matriz!$C$9)/SUM(Matriz!$C$5:$C$9),2)) | P25: =IFERROR(INDEX(Processos!$F$8:$F$17,MATCH(C25,Processos!$A$8:$A$17,0)),1) -> 1.017 | Q25: =IFERROR(INDEX(Matriz!$C$28:$C$33,MATCH(G25,Matriz!$A$28:$A$33,0)),0) -> 0 | R25: =IF(O25="","",ROUND(O25*P25+Q25,2)) | S25: =IF(R25="","",IF(R25>=Matriz!$C$19,4,IF(R25>=Matriz!$C$18,3,IF(R25>=Matriz!$C$17,2,1)))) | T25: =IF(S25="","",MAX(S25,IF(I25=5,Matriz!$C$23,0),IF(N25="Sim",Matriz!$C$24,0))) | U25: =IF(T25="","",CHOOSE(T25,"Baixa","Normal","Alta","Urgente")) | V25: =IF(T25="","",T25*1000+R25*10-IF(H25="",3,H25)/10-ROW()/1000000) | W25: =IF(V25="","",COUNTIF($V$5:$V$405,">"&V25)+1)
A26: 17tpepcdaee | B26: Avaliar automatização do processo de leads - WhatsApp vs CV Gadens | C26: Comercial Gadens | D26: Alexandre Marchiori Cruz | E26: sem prazo definido | G26: Automação ou sistema | O26: =IF(COUNT(I26:M26)<5,"",ROUND((I26*Matriz!$C$5+J26*Matriz!$C$6+K26*Matriz!$C$7+L26*Matriz!$C$8+M26*Matriz!$C$9)/SUM(Matriz!$C$5:$C$9),2)) | P26: =IFERROR(INDEX(Processos!$F$8:$F$17,MATCH(C26,Processos!$A$8:$A$17,0)),1) -> 1.017 | Q26: =IFERROR(INDEX(Matriz!$C$28:$C$33,MATCH(G26,Matriz!$A$28:$A$33,0)),0) -> 0 | R26: =IF(O26="","",ROUND(O26*P26+Q26,2)) | S26: =IF(R26="","",IF(R26>=Matriz!$C$19,4,IF(R26>=Matriz!$C$18,3,IF(R26>=Matriz!$C$17,2,1)))) | T26: =IF(S26="","",MAX(S26,IF(I26=5,Matriz!$C$23,0),IF(N26="Sim",Matriz!$C$24,0))) | U26: =IF(T26="","",CHOOSE(T26,"Baixa","Normal","Alta","Urgente")) | V26: =IF(T26="","",T26*1000+R26*10-IF(H26="",3,H26)/10-ROW()/1000000) | W26: =IF(V26="","",COUNTIF($V$5:$V$405,">"&V26)+1)
A27: 17tpepcpr2y | B27: Avaliar bloqueio de unidades permutadas dentro do Mega a partir do CV | C27: Comercial Gadens | D27: Alexandre Marchiori Cruz | E27: sem prazo definido | G27: Controle | O27: =IF(COUNT(I27:M27)<5,"",ROUND((I27*Matriz!$C$5+J27*Matriz!$C$6+K27*Matriz!$C$7+L27*Matriz!$C$8+M27*Matriz!$C$9)/SUM(Matriz!$C$5:$C$9),2)) | P27: =IFERROR(INDEX(Processos!$F$8:$F$17,MATCH(C27,Processos!$A$8:$A$17,0)),1) -> 1.017 | Q27: =IFERROR(INDEX(Matriz!$C$28:$C$33,MATCH(G27,Matriz!$A$28:$A$33,0)),0) -> 0.3 | R27: =IF(O27="","",ROUND(O27*P27+Q27,2)) | S27: =IF(R27="","",IF(R27>=Matriz!$C$19,4,IF(R27>=Matriz!$C$18,3,IF(R27>=Matriz!$C$17,2,1)))) | T27: =IF(S27="","",MAX(S27,IF(I27=5,Matriz!$C$23,0),IF(N27="Sim",Matriz!$C$24,0))) | U27: =IF(T27="","",CHOOSE(T27,"Baixa","Normal","Alta","Urgente")) | V27: =IF(T27="","",T27*1000+R27*10-IF(H27="",3,H27)/10-ROW()/1000000) | W27: =IF(V27="","",COUNTIF($V$5:$V$405,">"&V27)+1)
A28: 17tpepcpr26 | B28: Avaliar com as construtoras prazo máximo para alteração de opção de planta | C28: Comercial Gadens | D28: Hellen Venturoso | E28: sem prazo definido | G28: Definição ou decisão | O28: =IF(COUNT(I28:M28)<5,"",ROUND((I28*Matriz!$C$5+J28*Matriz!$C$6+K28*Matriz!$C$7+L28*Matriz!$C$8+M28*Matriz!$C$9)/SUM(Matriz!$C$5:$C$9),2)) | P28: =IFERROR(INDEX(Processos!$F$8:$F$17,MATCH(C28,Processos!$A$8:$A$17,0)),1) -> 1.017 | Q28: =IFERROR(INDEX(Matriz!$C$28:$C$33,MATCH(G28,Matriz!$A$28:$A$33,0)),0) -> 0 | R28: =IF(O28="","",ROUND(O28*P28+Q28,2)) | S28: =IF(R28="","",IF(R28>=Matriz!$C$19,4,IF(R28>=Matriz!$C$18,3,IF(R28>=Matriz!$C$17,2,1)))) | T28: =IF(S28="","",MAX(S28,IF(I28=5,Matriz!$C$23,0),IF(N28="Sim",Matriz!$C$24,0))) | U28: =IF(T28="","",CHOOSE(T28,"Baixa","Normal","Alta","Urgente")) | V28: =IF(T28="","",T28*1000+R28*10-IF(H28="",3,H28)/10-ROW()/1000000) | W28: =IF(V28="","",COUNTIF($V$5:$V$405,">"&V28)+1)
A29: 17tpepcgqnr | B29: Avaliar impacto da reforma tributária na migração de pessoa física para pessoa jurídica | C29: Comercial Gadens | D29: Érica Ferreira Tavares Silva Caldeira, Paulo Tavares | E29: sem prazo definido | G29: Definição ou decisão | O29: =IF(COUNT(I29:M29)<5,"",ROUND((I29*Matriz!$C$5+J29*Matriz!$C$6+K29*Matriz!$C$7+L29*Matriz!$C$8+M29*Matriz!$C$9)/SUM(Matriz!$C$5:$C$9),2)) | P29: =IFERROR(INDEX(Processos!$F$8:$F$17,MATCH(C29,Processos!$A$8:$A$17,0)),1) -> 1.017 | Q29: =IFERROR(INDEX(Matriz!$C$28:$C$33,MATCH(G29,Matriz!$A$28:$A$33,0)),0) -> 0 | R29: =IF(O29="","",ROUND(O29*P29+Q29,2)) | S29: =IF(R29="","",IF(R29>=Matriz!$C$19,4,IF(R29>=Matriz!$C$18,3,IF(R29>=Matriz!$C$17,2,1)))) | T29: =IF(S29="","",MAX(S29,IF(I29=5,Matriz!$C$23,0),IF(N29="Sim",Matriz!$C$24,0))) | U29: =IF(T29="","",CHOOSE(T29,"Baixa","Normal","Alta","Urgente")) | V29: =IF(T29="","",T29*1000+R29*10-IF(H29="",3,H29)/10-ROW()/1000000) | W29: =IF(V29="","",COUNTIF($V$5:$V$405,">"&V29)+1)
A30: 17tpepcpr2q | B30: Avaliar informação automática sobre cadastro do contrato de permuta financeira, através do Mega Inteligence, ou solução similar | C30: Comercial Gadens | D30: Alexandre Marchiori Cruz | E30: sem prazo definido | G30: Automação ou sistema | O30: =IF(COUNT(I30:M30)<5,"",ROUND((I30*Matriz!$C$5+J30*Matriz!$C$6+K30*Matriz!$C$7+L30*Matriz!$C$8+M30*Matriz!$C$9)/SUM(Matriz!$C$5:$C$9),2)) | P30: =IFERROR(INDEX(Processos!$F$8:$F$17,MATCH(C30,Processos!$A$8:$A$17,0)),1) -> 1.017 | Q30: =IFERROR(INDEX(Matriz!$C$28:$C$33,MATCH(G30,Matriz!$A$28:$A$33,0)),0) -> 0 | R30: =IF(O30="","",ROUND(O30*P30+Q30,2)) | S30: =IF(R30="","",IF(R30>=Matriz!$C$19,4,IF(R30>=Matriz!$C$18,3,IF(R30>=Matriz!$C$17,2,1)))) | T30: =IF(S30="","",MAX(S30,IF(I30=5,Matriz!$C$23,0),IF(N30="Sim",Matriz!$C$24,0))) | U30: =IF(T30="","",CHOOSE(T30,"Baixa","Normal","Alta","Urgente")) | V30: =IF(T30="","",T30*1000+R30*10-IF(H30="",3,H30)/10-ROW()/1000000) | W30: =IF(V30="","",COUNTIF($V$5:$V$405,">"&V30)+1)
A31: 17tpepcpr2c | B31: Avaliar padronização de nomenclatura das permutas / justificativas de bloqueio no CV (Make It e Gadens) | C31: Comercial Gadens | D31: André Garcia Vilas Boas, Mônica Massaneiro | E31: sem prazo definido | G31: Controle | O31: =IF(COUNT(I31:M31)<5,"",ROUND((I31*Matriz!$C$5+J31*Matriz!$C$6+K31*Matriz!$C$7+L31*Matriz!$C$8+M31*Matriz!$C$9)/SUM(Matriz!$C$5:$C$9),2)) | P31: =IFERROR(INDEX(Processos!$F$8:$F$17,MATCH(C31,Processos!$A$8:$A$17,0)),1) -> 1.017 | Q31: =IFERROR(INDEX(Matriz!$C$28:$C$33,MATCH(G31,Matriz!$A$28:$A$33,0)),0) -> 0.3 | R31: =IF(O31="","",ROUND(O31*P31+Q31,2)) | S31: =IF(R31="","",IF(R31>=Matriz!$C$19,4,IF(R31>=Matriz!$C$18,3,IF(R31>=Matriz!$C$17,2,1)))) | T31: =IF(S31="","",MAX(S31,IF(I31=5,Matriz!$C$23,0),IF(N31="Sim",Matriz!$C$24,0))) | U31: =IF(T31="","",CHOOSE(T31,"Baixa","Normal","Alta","Urgente")) | V31: =IF(T31="","",T31*1000+R31*10-IF(H31="",3,H31)/10-ROW()/1000000) | W31: =IF(V31="","",COUNTIF($V$5:$V$405,">"&V31)+1)
A32: 17tpepcdm2y | B32: Avaliar plataforma para registro de campanhas exclusivas (hoje efetuado no Sharepoint) | C32: Comercial Gadens | D32: Alexandre Marchiori Cruz | E32: sem prazo definido | G32: Automação ou sistema | O32: =IF(COUNT(I32:M32)<5,"",ROUND((I32*Matriz!$C$5+J32*Matriz!$C$6+K32*Matriz!$C$7+L32*Matriz!$C$8+M32*Matriz!$C$9)/SUM(Matriz!$C$5:$C$9),2)) | P32: =IFERROR(INDEX(Processos!$F$8:$F$17,MATCH(C32,Processos!$A$8:$A$17,0)),1) -> 1.017 | Q32: =IFERROR(INDEX(Matriz!$C$28:$C$33,MATCH(G32,Matriz!$A$28:$A$33,0)),0) -> 0 | R32: =IF(O32="","",ROUND(O32*P32+Q32,2)) | S32: =IF(R32="","",IF(R32>=Matriz!$C$19,4,IF(R32>=Matriz!$C$18,3,IF(R32>=Matriz!$C$17,2,1)))) | T32: =IF(S32="","",MAX(S32,IF(I32=5,Matriz!$C$23,0),IF(N32="Sim",Matriz!$C$24,0))) | U32: =IF(T32="","",CHOOSE(T32,"Baixa","Normal","Alta","Urgente")) | V32: =IF(T32="","",T32*1000+R32*10-IF(H32="",3,H32)/10-ROW()/1000000) | W32: =IF(V32="","",COUNTIF($V$5:$V$405,">"&V32)+1)
... A34: 17tpepcenxf | B34: Avaliar trava no CV sobre comissão dos contratos vendidos por modalidade - Gadens | C34: Comercial Gadens | D34: Alexandre Marchiori Cruz | E34: sem prazo definido | G34: Controle | O34: =IF(COUNT(I34:M34)<5,"",ROUND((I34*Matriz!$C$5+J34*Matriz!$C$6+K34*Matriz!$C$7+L34*Matriz!$C$8+M34*Matriz!$C$9)/SUM(Matriz!$C$5:$C$9),2)) | P34: =IFERROR(INDEX(Processos!$F$8:$F$17,MATCH(C34,Processos!$A$8:$A$17,0)),1) -> 1.017 | Q34: =IFERROR(INDEX(Matriz!$C$28:$C$33,MATCH(G34,Matriz!$A$28:$A$33,0)),0) -> 0.3 | R34: =IF(O34="","",ROUND(O34*P34+Q34,2)) | S34: =IF(R34="","",IF(R34>=Matriz!$C$19,4,IF(R34>=Matriz!$C$18,3,IF(R34>=Matriz!$C$17,2,1)))) | T34: =IF(S34="","",MAX(S34,IF(I34=5,Matriz!$C$23,0),IF(N34="Sim",Matriz!$C$24,0))) | U34: =IF(T34="","",CHOOSE(T34,"Baixa","Normal","Alta","Urgente")) | V34: =IF(T34="","",T34*1000+R34*10-IF(H34="",3,H34)/10-ROW()/1000000) | W34: =IF(V34="","",COUNTIF($V$5:$V$405,">"&V34)+1)
A35: 17tpepcgkv5 | B35: Avaliar venda via consórcio | C35: Comercial Gadens | D35: Marcelo Renato Nascimento Cerqueira | E35: sem prazo definido | G35: Definição ou decisão | H35: 3 | I35: 2 | J35: 3 | K35: 1 | L35: 3 | M35: 1 | N35: Não | O35: =IF(COUNT(I35:M35)<5,"",ROUND((I35*Matriz!$C$5+J35*Matriz!$C$6+K35*Matriz!$C$7+L35*Matriz!$C$8+M35*Matriz!$C$9)/SUM(Matriz!$C$5:$C$9),2)) -> 2 | P35: =IFERROR(INDEX(Processos!$F$8:$F$17,MATCH(C35,Processos!$A$8:$A$17,0)),1) -> 1.017 | Q35: =IFERROR(INDEX(Matriz!$C$28:$C$33,MATCH(G35,Matriz!$A$28:$A$33,0)),0) -> 0 | R35: =IF(O35="","",ROUND(O35*P35+Q35,2)) -> 2.03 | S35: =IF(R35="","",IF(R35>=Matriz!$C$19,4,IF(R35>=Matriz!$C$18,3,IF(R35>=Matriz!$C$17,2,1)))) -> 1 | T35: =IF(S35="","",MAX(S35,IF(I35=5,Matriz!$C$23,0),IF(N35="Sim",Matriz!$C$24,0))) -> 1 | U35: =IF(T35="","",CHOOSE(T35,"Baixa","Normal","Alta","Urgente")) -> Baixa | V35: =IF(T35="","",T35*1000+R35*10-IF(H35="",3,H35)/10-ROW()/1000000) -> 1020 | W35: =IF(V35="","",COUNTIF($V$5:$V$405,">"&V35)+1) -> 11 | X35: Âncora (proposta) | Y35: Avaliar uma modalidade nova de venda: decisão, sem risco imediato.
A36: 17tpepcpr2b | B36: Avaliar viabilidade de continuar SPE distratada ou necessidade de uma nova abertura | C36: Comercial Gadens | D36: Paulo Tavares | E36: sem prazo definido | G36: Definição ou decisão | O36: =IF(COUNT(I36:M36)<5,"",ROUND((I36*Matriz!$C$5+J36*Matriz!$C$6+K36*Matriz!$C$7+L36*Matriz!$C$8+M36*Matriz!$C$9)/SUM(Matriz!$C$5:$C$9),2)) | P36: =IFERROR(INDEX(Processos!$F$8:$F$17,MATCH(C36,Processos!$A$8:$A$17,0)),1) -> 1.017 | Q36: =IFERROR(INDEX(Matriz!$C$28:$C$33,MATCH(G36,Matriz!$A$28:$A$33,0)),0) -> 0 | R36: =IF(O36="","",ROUND(O36*P36+Q36,2)) | S36: =IF(R36="","",IF(R36>=Matriz!$C$19,4,IF(R36>=Matriz!$C$18,3,IF(R36>=Matriz!$C$17,2,1)))) | T36: =IF(S36="","",MAX(S36,IF(I36=5,Matriz!$C$23,0),IF(N36="Sim",Matriz!$C$24,0))) | U36: =IF(T36="","",CHOOSE(T36,"Baixa","Normal","Alta","Urgente")) | V36: =IF(T36="","",T36*1000+R36*10-IF(H36="",3,H36)/10-ROW()/1000000) | W36: =IF(V36="","",COUNTIF($V$5:$V$405,">"&V36)+1)
A37: 17tpepcpr24 | B37: Criar campo no CV para permutante e tipos de permuta | C37: Comercial Gadens | D37: Alexandre Marchiori Cruz | E37: sem prazo definido | G37: Automação ou sistema | H37: 2 | I37: 3 | J37: 3 | K37: 1 | L37: 2 | M37: 4 | N37: Não | O37: =IF(COUNT(I37:M37)<5,"",ROUND((I37*Matriz!$C$5+J37*Matriz!$C$6+K37*Matriz!$C$7+L37*Matriz!$C$8+M37*Matriz!$C$9)/SUM(Matriz!$C$5:$C$9),2)) -> 2.6 | P37: =IFERROR(INDEX(Processos!$F$8:$F$17,MATCH(C37,Processos!$A$8:$A$17,0)),1) -> 1.017 | Q37: =IFERROR(INDEX(Matriz!$C$28:$C$33,MATCH(G37,Matriz!$A$28:$A$33,0)),0) -> 0 | R37: =IF(O37="","",ROUND(O37*P37+Q37,2)) -> 2.64 | S37: =IF(R37="","",IF(R37>=Matriz!$C$19,4,IF(R37>=Matriz!$C$18,3,IF(R37>=Matriz!$C$17,2,1)))) -> 2 | T37: =IF(S37="","",MAX(S37,IF(I37=5,Matriz!$C$23,0),IF(N37="Sim",Matriz!$C$24,0))) -> 2 | U37: =IF(T37="","",CHOOSE(T37,"Baixa","Normal","Alta","Urgente")) -> Normal | V37: =IF(T37="","",T37*1000+R37*10-IF(H37="",3,H37)/10-ROW()/1000000) -> 2026.2 | W37: =IF(V37="","",COUNTIF($V$5:$V$405,">"&V37)+1) -> 10 | X37: Âncora (proposta) | Y37: Campo de permutante e tipos de permuta no CV: vários fluxos de permuta dependem dele.
A38: 17tpepcdg1x | B38: Criar lista de fornecedores para base - Sergio apoio Mariane; | C38: Comercial Gadens | D38: Sergio Lopes | E38: sem prazo definido | G38: Definição ou decisão | O38: =IF(COUNT(I38:M38)<5,"",ROUND((I38*Matriz!$C$5+J38*Matriz!$C$6+K38*Matriz!$C$7+L38*Matriz!$C$8+M38*Matriz!$C$9)/SUM(Matriz!$C$5:$C$9),2)) | P38: =IFERROR(INDEX(Processos!$F$8:$F$17,MATCH(C38,Processos!$A$8:$A$17,0)),1) -> 1.017 | Q38: =IFERROR(INDEX(Matriz!$C$28:$C$33,MATCH(G38,Matriz!$A$28:$A$33,0)),0) -> 0 | R38: =IF(O38="","",ROUND(O38*P38+Q38,2)) | S38: =IF(R38="","",IF(R38>=Matriz!$C$19,4,IF(R38>=Matriz!$C$18,3,IF(R38>=Matriz!$C$17,2,1)))) | T38: =IF(S38="","",MAX(S38,IF(I38=5,Matriz!$C$23,0),IF(N38="Sim",Matriz!$C$24,0))) | U38: =IF(T38="","",CHOOSE(T38,"Baixa","Normal","Alta","Urgente")) | V38: =IF(T38="","",T38*1000+R38*10-IF(H38="",3,H38)/10-ROW()/1000000) | W38: =IF(V38="","",COUNTIF($V$5:$V$405,">"&V38)+1)
A39: 17tpepcdg20 | B39: Definir centro de custo e verba de manutenção de estoque | C39: Comercial Gadens | D39: Mônica Massaneiro | E39: sem prazo definido | G39: Definição ou decisão | O39: =IF(COUNT(I39:M39)<5,"",ROUND((I39*Matriz!$C$5+J39*Matriz!$C$6+K39*Matriz!$C$7+L39*Matriz!$C$8+M39*Matriz!$C$9)/SUM(Matriz!$C$5:$C$9),2)) | P39: =IFERROR(INDEX(Processos!$F$8:$F$17,MATCH(C39,Processos!$A$8:$A$17,0)),1) -> 1.017 | Q39: =IFERROR(INDEX(Matriz!$C$28:$C$33,MATCH(G39,Matriz!$A$28:$A$33,0)),0) -> 0 | R39: =IF(O39="","",ROUND(O39*P39+Q39,2)) | S39: =IF(R39="","",IF(R39>=Matriz!$C$19,4,IF(R39>=Matriz!$C$18,3,IF(R39>=Matriz!$C$17,2,1)))) | T39: =IF(S39="","",MAX(S39,IF(I39=5,Matriz!$C$23,0),IF(N39="Sim",Matriz!$C$24,0))) | U39: =IF(T39="","",CHOOSE(T39,"Baixa","Normal","Alta","Urgente")) | V39: =IF(T39="","",T39*1000+R39*10-IF(H39="",3,H39)/10-ROW()/1000000) | W39: =IF(V39="","",COUNTIF($V$5:$V$405,">"&V39)+1)
A40: 17tpepcgqnq | B40: Definir critérios da venda direta | C40: Comercial Gadens | D40: Érica Ferreira Tavares Silva Caldeira | E40: sem prazo definido | G40: Definição ou decisão | O40: =IF(COUNT(I40:M40)<5,"",ROUND((I40*Matriz!$C$5+J40*Matriz!$C$6+K40*Matriz!$C$7+L40*Matriz!$C$8+M40*Matriz!$C$9)/SUM(Matriz!$C$5:$C$9),2)) | P40: =IFERROR(INDEX(Processos!$F$8:$F$17,MATCH(C40,Processos!$A$8:$A$17,0)),1) -> 1.017 | Q40: =IFERROR(INDEX(Matriz!$C$28:$C$33,MATCH(G40,Matriz!$A$28:$A$33,0)),0) -> 0 | R40: =IF(O40="","",ROUND(O40*P40+Q40,2)) | S40: =IF(R40="","",IF(R40>=Matriz!$C$19,4,IF(R40>=Matriz!$C$18,3,IF(R40>=Matriz!$C$17,2,1)))) | T40: =IF(S40="","",MAX(S40,IF(I40=5,Matriz!$C$23,0),IF(N40="Sim",Matriz!$C$24,0))) | U40: =IF(T40="","",CHOOSE(T40,"Baixa","Normal","Alta","Urgente")) | V40: =IF(T40="","",T40*1000+R40*10-IF(H40="",3,H40)/10-ROW()/1000000) | W40: =IF(V40="","",COUNTIF($V$5:$V$405,">"&V40)+1)
A41: 17tpepcdm33 | B41: Definir fluxo de contratos personalizados no CV e treinar os envolvidos - Gadens | C41: Comercial Gadens | D41: Alexandre Marchiori Cruz | E41: sem prazo definido | G41: Treinamento | O41: =IF(COUNT(I41:M41)<5,"",ROUND((I41*Matriz!$C$5+J41*Matriz!$C$6+K41*Matriz!$C$7+L41*Matriz!$C$8+M41*Matriz!$C$9)/SUM(Matriz!$C$5:$C$9),2)) | P41: =IFERROR(INDEX(Processos!$F$8:$F$17,MATCH(C41,Processos!$A$8:$A$17,0)),1) -> 1.017 | Q41: =IFERROR(INDEX(Matriz!$C$28:$C$33,MATCH(G41,Matriz!$A$28:$A$33,0)),0) -> -0.2 | R41: =IF(O41="","",ROUND(O41*P41+Q41,2)) | S41: =IF(R41="","",IF(R41>=Matriz!$C$19,4,IF(R41>=Matriz!$C$18,3,IF(R41>=Matriz!$C$17,2,1)))) | T41: =IF(S41="","",MAX(S41,IF(I41=5,Matriz!$C$23,0),IF(N41="Sim",Matriz!$C$24,0))) | U41: =IF(T41="","",CHOOSE(T41,"Baixa","Normal","Alta","Urgente")) | V41: =IF(T41="","",T41*1000+R41*10-IF(H41="",3,H41)/10-ROW()/1000000) | W41: =IF(V41="","",COUNTIF($V$5:$V$405,">"&V41)+1)
A42: 17tpepcpr2m | B42: Definir regras de comercialização das unidades pelo permutante - Make It e Gadens | C42: Comercial Gadens | D42: André Garcia Vilas Boas, Mônica Massaneiro | E42: sem prazo definido | G42: Definição ou decisão | O42: =IF(COUNT(I42:M42)<5,"",ROUND((I42*Matriz!$C$5+J42*Matriz!$C$6+K42*Matriz!$C$7+L42*Matriz!$C$8+M42*Matriz!$C$9)/SUM(Matriz!$C$5:$C$9),2)) | P42: =IFERROR(INDEX(Processos!$F$8:$F$17,MATCH(C42,Processos!$A$8:$A$17,0)),1) -> 1.017 | Q42: =IFERROR(INDEX(Matriz!$C$28:$C$33,MATCH(G42,Matriz!$A$28:$A$33,0)),0) -> 0 | R42: =IF(O42="","",ROUND(O42*P42+Q42,2)) | S42: =IF(R42="","",IF(R42>=Matriz!$C$19,4,IF(R42>=Matriz!$C$18,3,IF(R42>=Matriz!$C$17,2,1)))) | T42: =IF(S42="","",MAX(S42,IF(I42=5,Matriz!$C$23,0),IF(N42="Sim",Matriz!$C$24,0))) | U42: =IF(T42="","",CHOOSE(T42,"Baixa","Normal","Alta","Urgente")) | V42: =IF(T42="","",T42*1000+R42*10-IF(H42="",3,H42)/10-ROW()/1000000) | W42: =IF(V42="","",COUNTIF($V$5:$V$405,">"&V42)+1)
A43: 17tpepcdk0p | B43: Elaborar POP - Critérios de seleção de correspondentes | C43: Comercial Gadens | D43: Mônica Massaneiro | E43: sem prazo definido | G43: Documento normativo | O43: =IF(COUNT(I43:M43)<5,"",ROUND((I43*Matriz!$C$5+J43*Matriz!$C$6+K43*Matriz!$C$7+L43*Matriz!$C$8+M43*Matriz!$C$9)/SUM(Matriz!$C$5:$C$9),2)) | P43: =IFERROR(INDEX(Processos!$F$8:$F$17,MATCH(C43,Processos!$A$8:$A$17,0)),1) -> 1.017 | Q43: =IFERROR(INDEX(Matriz!$C$28:$C$33,MATCH(G43,Matriz!$A$28:$A$33,0)),0) -> 0 | R43: =IF(O43="","",ROUND(O43*P43+Q43,2)) | S43: =IF(R43="","",IF(R43>=Matriz!$C$19,4,IF(R43>=Matriz!$C$18,3,IF(R43>=Matriz!$C$17,2,1)))) | T43: =IF(S43="","",MAX(S43,IF(I43=5,Matriz!$C$23,0),IF(N43="Sim",Matriz!$C$24,0))) | U43: =IF(T43="","",CHOOSE(T43,"Baixa","Normal","Alta","Urgente")) | V43: =IF(T43="","",T43*1000+R43*10-IF(H43="",3,H43)/10-ROW()/1000000) | W43: =IF(V43="","",COUNTIF($V$5:$V$405,">"&V43)+1)
A44: 17tpepcdm30 | B44: Encerramento automático de contrato em caso de não pagamento de sinal | C44: Comercial Gadens | D44: Alexandre Marchiori Cruz | E44: sem prazo definido | G44: Definição ou decisão | O44: =IF(COUNT(I44:M44)<5,"",ROUND((I44*Matriz!$C$5+J44*Matriz!$C$6+K44*Matriz!$C$7+L44*Matriz!$C$8+M44*Matriz!$C$9)/SUM(Matriz!$C$5:$C$9),2)) | P44: =IFERROR(INDEX(Processos!$F$8:$F$17,MATCH(C44,Processos!$A$8:$A$17,0)),1) -> 1.017 | Q44: =IFERROR(INDEX(Matriz!$C$28:$C$33,MATCH(G44,Matriz!$A$28:$A$33,0)),0) -> 0 | R44: =IF(O44="","",ROUND(O44*P44+Q44,2)) | S44: =IF(R44="","",IF(R44>=Matriz!$C$19,4,IF(R44>=Matriz!$C$18,3,IF(R44>=Matriz!$C$17,2,1)))) | T44: =IF(S44="","",MAX(S44,IF(I44=5,Matriz!$C$23,0),IF(N44="Sim",Matriz!$C$24,0))) | U44: =IF(T44="","",CHOOSE(T44,"Baixa","Normal","Alta","Urgente")) | V44: =IF(T44="","",T44*1000+R44*10-IF(H44="",3,H44)/10-ROW()/1000000) | W44: =IF(V44="","",COUNTIF($V$5:$V$405,">"&V44)+1)
A45: 17tpepcdm32 | B45: Fluxo de proposta via CV | C45: Comercial Gadens | D45: Alexandre Marchiori Cruz | E45: sem prazo definido | G45: Automação ou sistema | O45: =IF(COUNT(I45:M45)<5,"",ROUND((I45*Matriz!$C$5+J45*Matriz!$C$6+K45*Matriz!$C$7+L45*Matriz!$C$8+M45*Matriz!$C$9)/SUM(Matriz!$C$5:$C$9),2)) | P45: =IFERROR(INDEX(Processos!$F$8:$F$17,MATCH(C45,Processos!$A$8:$A$17,0)),1) -> 1.017 | Q45: =IFERROR(INDEX(Matriz!$C$28:$C$33,MATCH(G45,Matriz!$A$28:$A$33,0)),0) -> 0 | R45: =IF(O45="","",ROUND(O45*P45+Q45,2)) | S45: =IF(R45="","",IF(R45>=Matriz!$C$19,4,IF(R45>=Matriz!$C$18,3,IF(R45>=Matriz!$C$17,2,1)))) | T45: =IF(S45="","",MAX(S45,IF(I45=5,Matriz!$C$23,0),IF(N45="Sim",Matriz!$C$24,0))) | U45: =IF(T45="","",CHOOSE(T45,"Baixa","Normal","Alta","Urgente")) | V45: =IF(T45="","",T45*1000+R45*10-IF(H45="",3,H45)/10-ROW()/1000000) | W45: =IF(V45="","",COUNTIF($V$5:$V$405,">"&V45)+1)
...
