Workbook

Sheet Leia-me
B2: Sugestão de prioridades: Urgente e Alta
B3: Projeto Next · Processos · lista "Implantação de Melhorias (5W2H)" · lida em 27/10/2026 · todas as atividades, de todos os status · proposta para validação
B5: O que é | C5: A matriz de prioridades aplicada a todas as 979 atividades do ClickUp (398 abertas, 502 concluídas e 79 canceladas). Mostra quais ficariam em Urgente e em Alta. A prioridade que já estava no ClickUp NÃO foi usada.
B6: Resultado | C6: Urgente: 56 atividades (5.7% do total). Alta: 166 atividades (17.0% do total). Faixas de referência: Urgente 5% a 10% e Alta 15% a 25%. Veja a aba Resumo.
B7: Como foi pontuado | C7: Cada atividade recebe nota de 1 a 5 em cinco critérios: risco de fraude e erro (30%), impacto financeiro (20%), obra e entrega (20%), exigência legal/CEF/compliance (15%) e dependência (15%). A média é multiplicada pelo fator do processo (0,9 a 1,1) e somada ao ajuste da natureza (controle +0,3; indicador −0,3; treinamento −0,2). Esforço não entra na nota: só desempata.
B8: Cortes e vetos | C8: Urgente a partir de 3,9; Alta a partir de 3,3; Normal a partir de 2,5. Risco 5 sobe a atividade para, no mínimo, Alta. "Para obra ou repasse da CEF" sobe para Urgente. O corte de Urgente era 4,0 na proposta anterior; com ele ficavam 41 atividades (4,2%), abaixo da faixa mínima de 5%. Baixei para 3,9.
B9: Quem pontuou | C9: 515 atividades foram pontuadas por mim, uma a uma, a partir do nome, do processo, do status e do contexto que li do Projeto Next. As outras 464 usaram uma regra automática por palavras do nome, limitada a nota 3 em cada critério, e só aparecem nas listas se isso bastar para chegar lá (a coluna "Origem da nota" mostra qual foi).
B10: Limites desta leitura | C10: Li o NOME da atividade, não a descrição completa nem o histórico. As notas são PROPOSTA minha e devem ser contestadas pelo responsável e pelo gestor da área. Concluídas e canceladas entram para mostrar se a matriz concorda com o que a equipe fez; para decidir o que fazer agora, filtre Situação = Aberta. Atividades duplicadas entre Gadens e Make It recebem a mesma nota.
B11: Atenção | C11: Entre as abertas, Urgente + Alta ficam acima da trava de capacidade de 30% (veja a aba Resumo). Isso indica excesso de coisa importante para a equipe tocar ao mesmo tempo, e não necessariamente erro da escala.
B12: Abas | C12: Resumo: faixas, processos e responsáveis · Urgente e Alta: as listas sugeridas (abertas primeiro, concluídas e canceladas em cinza) · Todas: as atividades com a conta (fórmulas vivas) · Parametros: pesos, cortes, vetos e fatores editáveis.
B13: Cores | C13: Azul em fundo amarelo = pode editar. Fundo cinza = fórmula. Prioridade com as cores das bandeiras do ClickUp: vermelho Urgente, amarelo Alta, azul Normal, cinza Baixa.

Sheet Resumo
A1: Resumo: as faixas de prioridade
A2: Tudo calculado a partir da aba Todas. As faixas (azul) são a proposta de referência.
A4: Total de atividades | B4: =COUNTA(Todas!$B$5:$B$983) -> 979
A5: Abertas hoje | B5: =COUNTIF(Todas!$H$5:$H$983,"Aberta") -> 398
A6: Concluídas | B6: =COUNTIF(Todas!$H$5:$H$983,"Concluída") -> 502
A7: Canceladas | B7: =COUNTIF(Todas!$H$5:$H$983,"Cancelada") -> 79
A9: Categoria | B9: Faixa mín. | C9: Faixa máx. | D9: Quantidade (total) | E9: % do total | F9: Situação no total | G9: Abertas | H9: % das abertas
A10: 4 · Urgente | B10: 0.05 | C10: 0.1 | D10: =COUNTIF(Todas!$W$5:$W$983,4) -> 56 | E10: =D10/$B$4 -> 0.057201226 | F10: =IF(E10<B10,"abaixo da faixa",IF(E10>C10,"acima da faixa","dentro da faixa")) -> dentro da faixa | G10: =COUNTIFS(Todas!$W$5:$W$983,4,Todas!$H$5:$H$983,"Aberta") -> 32 | H10: =G10/$B$5 -> 0.08040201
A11: 3 · Alta | B11: 0.15 | C11: 0.25 | D11: =COUNTIF(Todas!$W$5:$W$983,3) -> 166 | E11: =D11/$B$4 -> 0.16956078 | F11: =IF(E11<B11,"abaixo da faixa",IF(E11>C11,"acima da faixa","dentro da faixa")) -> dentro da faixa | G11: =COUNTIFS(Todas!$W$5:$W$983,3,Todas!$H$5:$H$983,"Aberta") -> 108 | H11: =G11/$B$5 -> 0.27135678
A12: 2 · Normal | D12: =COUNTIF(Todas!$W$5:$W$983,2) -> 245 | E12: =D12/$B$4 -> 0.25025536 | F12: — | G12: =COUNTIFS(Todas!$W$5:$W$983,2,Todas!$H$5:$H$983,"Aberta") -> 116 | H12: =G12/$B$5 -> 0.29145729
A13: 1 · Baixa | D13: =COUNTIF(Todas!$W$5:$W$983,1) -> 512 | E13: =D13/$B$4 -> 0.52298264 | F13: — | G13: =COUNTIFS(Todas!$W$5:$W$983,1,Todas!$H$5:$H$983,"Aberta") -> 142 | H13: =G13/$B$5 -> 0.35678392
A14: Urgente + Alta | C14: 0.3 | D14: =D10+D11 -> 222 | E14: =D14/$B$4 -> 0.226762 | F14: =IF(E14>C14,"acima da trava","dentro da trava") -> dentro da trava | G14: =G10+G11 -> 140 | H14: =G14/$B$5 -> 0.35175879
A15: Trava de capacidade nas abertas (Urgente + Alta ≤) | C15: 0.3 | F15: =IF(H14>C15,"acima da trava","dentro da trava") -> acima da trava | H15: =H14 -> 0.35175879
A16: A faixa vale para o total (as concluídas mostram se a matriz concorda com o que a equipe já fez). A trava de capacidade vale para as abertas: é o que a equipe ainda precisa tocar.
A18: Processo | B18: Total | C18: Abertas | D18: Urgente (total) | E18: Alta (total) | F18: Urgente (abertas) | G18: Alta (abertas)
A19: Incorporação Make It | B19: =COUNTIF(Todas!$D$5:$D$983,A19) -> 66 | C19: =COUNTIFS(Todas!$D$5:$D$983,A19,Todas!$H$5:$H$983,"Aberta") -> 16 | D19: =COUNTIFS(Todas!$D$5:$D$983,$A19,Todas!$W$5:$W$983,4) -> 2 | E19: =COUNTIFS(Todas!$D$5:$D$983,$A19,Todas!$W$5:$W$983,3) -> 4 | F19: =COUNTIFS(Todas!$D$5:$D$983,$A19,Todas!$W$5:$W$983,4,Todas!$H$5:$H$983,"Aberta") -> 1 | G19: =COUNTIFS(Todas!$D$5:$D$983,$A19,Todas!$W$5:$W$983,3,Todas!$H$5:$H$983,"Aberta") -> 4
A20: Incorporação Gadens | B20: =COUNTIF(Todas!$D$5:$D$983,A20) -> 54 | C20: =COUNTIFS(Todas!$D$5:$D$983,A20,Todas!$H$5:$H$983,"Aberta") -> 12 | D20: =COUNTIFS(Todas!$D$5:$D$983,$A20,Todas!$W$5:$W$983,4) -> 1 | E20: =COUNTIFS(Todas!$D$5:$D$983,$A20,Todas!$W$5:$W$983,3) -> 4 | F20: =COUNTIFS(Todas!$D$5:$D$983,$A20,Todas!$W$5:$W$983,4,Todas!$H$5:$H$983,"Aberta") -> 0 | G20: =COUNTIFS(Todas!$D$5:$D$983,$A20,Todas!$W$5:$W$983,3,Todas!$H$5:$H$983,"Aberta") -> 3
A21: Engenharia | B21: =COUNTIF(Todas!$D$5:$D$983,A21) -> 271 | C21: =COUNTIFS(Todas!$D$5:$D$983,A21,Todas!$H$5:$H$983,"Aberta") -> 74 | D21: =COUNTIFS(Todas!$D$5:$D$983,$A21,Todas!$W$5:$W$983,4) -> 11 | E21: =COUNTIFS(Todas!$D$5:$D$983,$A21,Todas!$W$5:$W$983,3) -> 30 | F21: =COUNTIFS(Todas!$D$5:$D$983,$A21,Todas!$W$5:$W$983,4,Todas!$H$5:$H$983,"Aberta") -> 8 | G21: =COUNTIFS(Todas!$D$5:$D$983,$A21,Todas!$W$5:$W$983,3,Todas!$H$5:$H$983,"Aberta") -> 21
A22: Novos Negócios | B22: =COUNTIF(Todas!$D$5:$D$983,A22) -> 125 | C22: =COUNTIFS(Todas!$D$5:$D$983,A22,Todas!$H$5:$H$983,"Aberta") -> 30 | D22: =COUNTIFS(Todas!$D$5:$D$983,$A22,Todas!$W$5:$W$983,4) -> 13 | E22: =COUNTIFS(Todas!$D$5:$D$983,$A22,Todas!$W$5:$W$983,3) -> 23 | F22: =COUNTIFS(Todas!$D$5:$D$983,$A22,Todas!$W$5:$W$983,4,Todas!$H$5:$H$983,"Aberta") -> 3 | G22: =COUNTIFS(Todas!$D$5:$D$983,$A22,Todas!$W$5:$W$983,3,Todas!$H$5:$H$983,"Aberta") -> 4
A23: Suprimentos | B23: =COUNTIF(Todas!$D$5:$D$983,A23) -> 123 | C23: =COUNTIFS(Todas!$D$5:$D$983,A23,Todas!$H$5:$H$983,"Aberta") -> 33 | D23: =COUNTIFS(Todas!$D$5:$D$983,$A23,Todas!$W$5:$W$983,4) -> 5 | E23: =COUNTIFS(Todas!$D$5:$D$983,$A23,Todas!$W$5:$W$983,3) -> 19 | F23: =COUNTIFS(Todas!$D$5:$D$983,$A23,Todas!$W$5:$W$983,4,Todas!$H$5:$H$983,"Aberta") -> 4 | G23: =COUNTIFS(Todas!$D$5:$D$983,$A23,Todas!$W$5:$W$983,3,Todas!$H$5:$H$983,"Aberta") -> 7
A24: Financeiro | B24: =COUNTIF(Todas!$D$5:$D$983,A24) -> 92 | C24: =COUNTIFS(Todas!$D$5:$D$983,A24,Todas!$H$5:$H$983,"Aberta") -> 39 | D24: =COUNTIFS(Todas!$D$5:$D$983,$A24,Todas!$W$5:$W$983,4) -> 5 | E24: =COUNTIFS(Todas!$D$5:$D$983,$A24,Todas!$W$5:$W$983,3) -> 17 | F24: =COUNTIFS(Todas!$D$5:$D$983,$A24,Todas!$W$5:$W$983,4,Todas!$H$5:$H$983,"Aberta") -> 2 | G24: =COUNTIFS(Todas!$D$5:$D$983,$A24,Todas!$W$5:$W$983,3,Todas!$H$5:$H$983,"Aberta") -> 11
A25: GMO | B25: =COUNTIF(Todas!$D$5:$D$983,A25) -> 123 | C25: =COUNTIFS(Todas!$D$5:$D$983,A25,Todas!$H$5:$H$983,"Aberta") -> 74 | D25: =COUNTIFS(Todas!$D$5:$D$983,$A25,Todas!$W$5:$W$983,4) -> 15 | E25: =COUNTIFS(Todas!$D$5:$D$983,$A25,Todas!$W$5:$W$983,3) -> 30 | F25: =COUNTIFS(Todas!$D$5:$D$983,$A25,Todas!$W$5:$W$983,4,Todas!$H$5:$H$983,"Aberta") -> 10 | G25: =COUNTIFS(Todas!$D$5:$D$983,$A25,Todas!$W$5:$W$983,3,Todas!$H$5:$H$983,"Aberta") -> 19
A26: Comercial Make It | B26: =COUNTIF(Todas!$D$5:$D$983,A26) -> 55 | C26: =COUNTIFS(Todas!$D$5:$D$983,A26,Todas!$H$5:$H$983,"Aberta") -> 53 | D26: =COUNTIFS(Todas!$D$5:$D$983,$A26,Todas!$W$5:$W$983,4) -> 1 | E26: =COUNTIFS(Todas!$D$5:$D$983,$A26,Todas!$W$5:$W$983,3) -> 20 | F26: =COUNTIFS(Todas!$D$5:$D$983,$A26,Todas!$W$5:$W$983,4,Todas!$H$5:$H$983,"Aberta") -> 1 | G26: =COUNTIFS(Todas!$D$5:$D$983,$A26,Todas!$W$5:$W$983,3,Todas!$H$5:$H$983,"Aberta") -> 20
A27: Comercial Gadens | B27: =COUNTIF(Todas!$D$5:$D$983,A27) -> 69 | C27: =COUNTIFS(Todas!$D$5:$D$983,A27,Todas!$H$5:$H$983,"Aberta") -> 66 | D27: =COUNTIFS(Todas!$D$5:$D$983,$A27,Todas!$W$5:$W$983,4) -> 3 | E27: =COUNTIFS(Todas!$D$5:$D$983,$A27,Todas!$W$5:$W$983,3) -> 19 | F27: =COUNTIFS(Todas!$D$5:$D$983,$A27,Todas!$W$5:$W$983,4,Todas!$H$5:$H$983,"Aberta") -> 3 | G27: =COUNTIFS(Todas!$D$5:$D$983,$A27,Todas!$W$5:$W$983,3,Todas!$H$5:$H$983,"Aberta") -> 19
A28: Sem processo definido | B28: =COUNTIF(Todas!$D$5:$D$983,A28) -> 1 | C28: =COUNTIFS(Todas!$D$5:$D$983,A28,Todas!$H$5:$H$983,"Aberta") -> 1 | D28: =COUNTIFS(Todas!$D$5:$D$983,$A28,Todas!$W$5:$W$983,4) -> 0 | E28: =COUNTIFS(Todas!$D$5:$D$983,$A28,Todas!$W$5:$W$983,3) -> 0 | F28: =COUNTIFS(Todas!$D$5:$D$983,$A28,Todas!$W$5:$W$983,4,Todas!$H$5:$H$983,"Aberta") -> 0 | G28: =COUNTIFS(Todas!$D$5:$D$983,$A28,Todas!$W$5:$W$983,3,Todas!$H$5:$H$983,"Aberta") -> 0
A29: Total | B29: =SUM(B19:B28) -> 979 | C29: =SUM(C19:C28) -> 398 | D29: =SUM(D19:D28) -> 56 | E29: =SUM(E19:E28) -> 166 | F29: =SUM(F19:F28) -> 32 | G29: =SUM(G19:G28) -> 108
A31: Urgentes abertas por responsável principal | D31: Limite por pessoa: | E31: 3
A32: Responsável | B32: Urgente (abertas) | C32: Alta (abertas) | D32: Total abertas | E32: Situação
A33: Bruna Oliveira Ribeiro | B33: =COUNTIFS(Todas!$E$5:$E$983,A33,Todas!$W$5:$W$983,4,Todas!$H$5:$H$983,"Aberta") -> 8 | C33: =COUNTIFS(Todas!$E$5:$E$983,A33,Todas!$W$5:$W$983,3,Todas!$H$5:$H$983,"Aberta") -> 5 | D33: =COUNTIFS(Todas!$E$5:$E$983,A33,Todas!$H$5:$H$983,"Aberta") -> 18 | E33: =IF(B33>$E$31,"acima do limite","ok") -> acima do limite
A34: Alexandre Marchiori Cruz | B34: =COUNTIFS(Todas!$E$5:$E$983,A34,Todas!$W$5:$W$983,4,Todas!$H$5:$H$983,"Aberta") -> 6 | C34: =COUNTIFS(Todas!$E$5:$E$983,A34,Todas!$W$5:$W$983,3,Todas!$H$5:$H$983,"Aberta") -> 22 | D34: =COUNTIFS(Todas!$E$5:$E$983,A34,Todas!$H$5:$H$983,"Aberta") -> 103 | E34: =IF(B34>$E$31,"acima do limite","ok") -> acima do limite
A35: Alessandro Braz | B35: =COUNTIFS(Todas!$E$5:$E$983,A35,Todas!$W$5:$W$983,4,Todas!$H$5:$H$983,"Aberta") -> 5 | C35: =COUNTIFS(Todas!$E$5:$E$983,A35,Todas!$W$5:$W$983,3,Todas!$H$5:$H$983,"Aberta") -> 4 | D35: =COUNTIFS(Todas!$E$5:$E$983,A35,Todas!$H$5:$H$983,"Aberta") -> 14 | E35: =IF(B35>$E$31,"acima do limite","ok") -> acima do limite
A36: Cleber Colin | B36: =COUNTIFS(Todas!$E$5:$E$983,A36,Todas!$W$5:$W$983,4,Todas!$H$5:$H$983,"Aberta") -> 3 | C36: =COUNTIFS(Todas!$E$5:$E$983,A36,Todas!$W$5:$W$983,3,Todas!$H$5:$H$983,"Aberta") -> 2 | D36: =COUNTIFS(Todas!$E$5:$E$983,A36,Todas!$H$5:$H$983,"Aberta") -> 19 | E36: =IF(B36>$E$31,"acima do limite","ok") -> ok
A37: Vanderlei Maturicio | B37: =COUNTIFS(Todas!$E$5:$E$983,A37,Todas!$W$5:$W$983,4,Todas!$H$5:$H$983,"Aberta") -> 3 | C37: =COUNTIFS(Todas!$E$5:$E$983,A37,Todas!$W$5:$W$983,3,Todas!$H$5:$H$983,"Aberta") -> 0 | D37: =COUNTIFS(Todas!$E$5:$E$983,A37,Todas!$H$5:$H$983,"Aberta") -> 4 | E37: =IF(B37>$E$31,"acima do limite","ok") -> ok
A38: Cleverton Parnoff | B38: =COUNTIFS(Todas!$E$5:$E$983,A38,Todas!$W$5:$W$983,4,Todas!$H$5:$H$983,"Aberta") -> 1 | C38: =COUNTIFS(Todas!$E$5:$E$983,A38,Todas!$W$5:$W$983,3,Todas!$H$5:$H$983,"Aberta") -> 8 | D38: =COUNTIFS(Todas!$E$5:$E$983,A38,Todas!$H$5:$H$983,"Aberta") -> 18 | E38: =IF(B38>$E$31,"acima do limite","ok") -> ok
A39: Edgard Machado Ferreira Junior | B39: =COUNTIFS(Todas!$E$5:$E$983,A39,Todas!$W$5:$W$983,4,Todas!$H$5:$H$983,"Aberta") -> 1 | C39: =COUNTIFS(Todas!$E$5:$E$983,A39,Todas!$W$5:$W$983,3,Todas!$H$5:$H$983,"Aberta") -> 8 | D39: =COUNTIFS(Todas!$E$5:$E$983,A39,Todas!$H$5:$H$983,"Aberta") -> 21 | E39: =IF(B39>$E$31,"acima do limite","ok") -> ok
A40: Hellen Venturoso | B40: =COUNTIFS(Todas!$E$5:$E$983,A40,Todas!$W$5:$W$983,4,Todas!$H$5:$H$983,"Aberta") -> 1 | C40: =COUNTIFS(Todas!$E$5:$E$983,A40,Todas!$W$5:$W$983,3,Todas!$H$5:$H$983,"Aberta") -> 5 | D40: =COUNTIFS(Todas!$E$5:$E$983,A40,Todas!$H$5:$H$983,"Aberta") -> 13 | E40: =IF(B40>$E$31,"acima do limite","ok") -> ok
A41: Mônica Massaneiro | B41: =COUNTIFS(Todas!$E$5:$E$983,A41,Todas!$W$5:$W$983,4,Todas!$H$5:$H$983,"Aberta") -> 1 | C41: =COUNTIFS(Todas!$E$5:$E$983,A41,Todas!$W$5:$W$983,3,Todas!$H$5:$H$983,"Aberta") -> 5 | D41: =COUNTIFS(Todas!$E$5:$E$983,A41,Todas!$H$5:$H$983,"Aberta") -> 14 | E41: =IF(B41>$E$31,"acima do limite","ok") -> ok
A42: Lizandra de Liz | B42: =COUNTIFS(Todas!$E$5:$E$983,A42,Todas!$W$5:$W$983,4,Todas!$H$5:$H$983,"Aberta") -> 1 | C42: =COUNTIFS(Todas!$E$5:$E$983,A42,Todas!$W$5:$W$983,3,Todas!$H$5:$H$983,"Aberta") -> 4 | D42: =COUNTIFS(Todas!$E$5:$E$983,A42,Todas!$H$5:$H$983,"Aberta") -> 24 | E42: =IF(B42>$E$31,"acima do limite","ok") -> ok
A43: Danielle Moraes | B43: =COUNTIFS(Todas!$E$5:$E$983,A43,Todas!$W$5:$W$983,4,Todas!$H$5:$H$983,"Aberta") -> 1 | C43: =COUNTIFS(Todas!$E$5:$E$983,A43,Todas!$W$5:$W$983,3,Todas!$H$5:$H$983,"Aberta") -> 2 | D43: =COUNTIFS(Todas!$E$5:$E$983,A43,Todas!$H$5:$H$983,"Aberta") -> 5 | E43: =IF(B43>$E$31,"acima do limite","ok") -> ok
A44: Roberto Dias | B44: =COUNTIFS(Todas!$E$5:$E$983,A44,Todas!$W$5:$W$983,4,Todas!$H$5:$H$983,"Aberta") -> 1 | C44: =COUNTIFS(Todas!$E$5:$E$983,A44,Todas!$W$5:$W$983,3,Todas!$H$5:$H$983,"Aberta") -> 0 | D44: =COUNTIFS(Todas!$E$5:$E$983,A44,Todas!$H$5:$H$983,"Aberta") -> 2 | E44: =IF(B44>$E$31,"acima do limite","ok") -> ok
...

Sheet Urgente
A1: Sugestão: Urgente
A2: Faixa sugerida de 5% a 10% do total. Total: 56 (32 abertas e 24 já concluídas ou canceladas). Fotografia do cálculo; para recalcular use a aba Todas.
A4: # | B4: Ordem geral | C4: Atividade (link no ClickUp) | D4: Processo | E4: Responsável principal | F4: Status no ClickUp | G4: Situação | H4: Natureza | I4: Nota final | J4: Cat. pela nota | K4: Veto aplicado? | L4: Risco | M4: Fin. | N4: Obra | O4: Legal | P4: Dep. | Q4: Esforço | R4: Por que entrou aqui
A5: 1 | B5: 2 | C5: Estruturar e aprovar Plano de Alçadas formal para aprovações de compras e contratações e disponibilizar em manual corporativo. (Falta de definição de plano de alçadas e autonomia.) | D5: Novos Negócios | E5: Bruna Oliveira Ribeiro | F5: em atraso | G5: Aberta | H5: Controle | I5: 4.89 | J5: 4 | L5: 5 | M5: 5 | N5: 3 | O5: 3 | P5: 5 | Q5: 4 | R5: risco de fraude/erro 5; impacto financeiro 5; dependência 5. é controle (+0,3).
A6: 2 | B6: 3 | C6: Definir alçada de assinaturas para contratação de mão de obra (Política de Contratos) | D6: GMO | E6: Bruna Oliveira Ribeiro | F6: em progresso | G6: Aberta | H6: Controle | I6: 4.69 | J6: 4 | L6: 5 | M6: 4 | N6: 3 | O6: 4 | P6: 5 | Q6: 3 | R6: risco de fraude/erro 5; dependência 5; impacto financeiro 4; exigência legal/CEF 4. é controle (+0,3).
A7: 3 | B7: 5 | C7: Definir fluxo de aprovação de contratos de empreiteiros | D7: GMO | E7: Bruna Oliveira Ribeiro | F7: em progresso | G7: Aberta | H7: Controle | I7: 4.44 | J7: 4 | L7: 4 | M7: 4 | N7: 4 | O7: 4 | P7: 4 | Q7: 3 | R7: risco de fraude/erro 4; obra e entrega 4; impacto financeiro 4; exigência legal/CEF 4; dependência 4. é controle (+0,3).
A8: 4 | B8: 6 | C8: Definir regra de perfis de acesso / Revisão dos acessos (colaboradores transferidos de empresa área, desligados etc.) | D8: Financeiro | E8: Roberto Dias | F8: em atraso | G8: Aberta | H8: Controle | I8: 4.4 | J8: 4 | L8: 5 | M8: 4 | N8: 2 | O8: 4 | P8: 4 | Q8: 3 | R8: risco de fraude/erro 5; impacto financeiro 4; exigência legal/CEF 4; dependência 4. é controle (+0,3).
A9: 5 | B9: 8 | C9: Implementar Indicador - Avanço físico versus avanço financeiro (medição) | D9: Engenharia | E9: Hellen Venturoso | F9: pausado | G9: Aberta | H9: Controle | I9: 4.37 | J9: 4 | L9: 4 | M9: 5 | N9: 4 | O9: 2 | P9: 3 | Q9: 3 | R9: impacto financeiro 5; risco de fraude/erro 4; obra e entrega 4. é controle (+0,3).
A10: 6 | B10: 9 | C10: Elaborar Política - Política de compras e contratação de fornecedores, contemplando critérios de aquisição de materiais e serviços, regras de utilização entre pedido de compra e cartão corporativo, fluxo de compras emergenciais, homologação de fornecedores, alçadas, responsabilidades e controles aplicáveis ao processo. | D10: Suprimentos | E10: Cleber Colin | F10: em atraso | G10: Aberta | H10: Documento normativo | I10: 4.36 | J10: 4 | L10: 4 | M10: 5 | N10: 3 | O10: 4 | P10: 5 | Q10: 4 | R10: impacto financeiro 5; dependência 5; risco de fraude/erro 4; exigência legal/CEF 4.
A11: 7 | B11: 10 | C11: Elaborar POP - Procedimento de interrupção de obra por motivos de segurança POP | D11: Engenharia | E11: Alessandro Braz | F11: em atraso | G11: Aberta | H11: Documento normativo | I11: 4.34 | J11: 4 | L11: 4 | M11: 3 | N11: 5 | O11: 5 | P11: 3 | Q11: 3 | R11: obra e entrega 5; exigência legal/CEF 5; risco de fraude/erro 4.
A12: 8 | B12: 11 | C12: Aplicar as penalidades contempladas em contrato com a empreiteira/construtora quando do não cumprimento dos itens apontados na vistoria (Andressa / Apoio Alessandro e Hellen)" | D12: Engenharia | E12: Edgard Machado Ferreira Junior | F12: em atraso | G12: Aberta | H12: Controle | I12: 4.31 | J12: 4 | L12: 4 | M12: 4 | N12: 4 | O12: 4 | P12: 2 | Q12: 2 | R12: risco de fraude/erro 4; obra e entrega 4; impacto financeiro 4; exigência legal/CEF 4. é controle (+0,3).
A13: 9 | B13: 12 | C13: Avaliar relatório de revisão de desembolso obra | D13: Engenharia | E13: Cleverton Parnoff | F13: em progresso | G13: Aberta | H13: Controle | I13: 4.31 | J13: 4 | L13: 4 | M13: 5 | N13: 3 | O13: 3 | P13: 3 | Q13: 3 | R13: impacto financeiro 5; risco de fraude/erro 4. é controle (+0,3).
A14: 10 | B14: 13 | C14: Implementar módulo de contratos de empreiteiros para contratos gerais | D14: GMO | E14: Bruna Oliveira Ribeiro | F14: em progresso | G14: Aberta | H14: Automação ou sistema | I14: 4.29 | J14: 4 | L14: 4 | M14: 4 | N14: 4 | O14: 4 | P14: 5 | Q14: 5 | R14: dependência 5; risco de fraude/erro 4; obra e entrega 4; impacto financeiro 4; exigência legal/CEF 4.
A15: 11 | B15: 14 | C15: Bloquear aditivo de data e reajuste para as obras no Approvo | D15: GMO | E15: Alexandre Marchiori Cruz | F15: sem prazo definido | G15: Aberta | H15: Controle | I15: 4.23 | J15: 4 | L15: 5 | M15: 4 | N15: 3 | O15: 3 | P15: 3 | Q15: 3 | R15: risco de fraude/erro 5; impacto financeiro 4. é controle (+0,3).
A16: 12 | B16: 15 | C16: Criar fluxo de auditoria de contrato vs serviço realizado | D16: GMO | E16: Alessandro Braz | F16: em progresso | G16: Aberta | H16: Controle | I16: 4.23 | J16: 4 | L16: 5 | M16: 4 | N16: 3 | O16: 3 | P16: 3 | Q16: 3 | R16: risco de fraude/erro 5; impacto financeiro 4. é controle (+0,3).
... A60: 56 | B60: 54 | C60: Elaboração de memoriais CEF - Problema: Prazo por falta de priorização Solução: Comunicação para fortalecer importância, Treinamento e Utlização do ClickUp | D60: Incorporação Make It | E60: Danielle Moraes | F60: concluído | G60: Concluída | H60: Definição ou decisão | I60: 3.91 | J60: 4 | L60: 3 | M60: 3 | N60: 5 | O60: 4 | P60: 3 | Q60: 3 | R60: obra e entrega 5; exigência legal/CEF 4.

Sheet Alta
A1: Sugestão: Alta
A2: Faixa sugerida de 15% a 25% do total. Total: 166 (108 abertas e 58 já concluídas ou canceladas). Fotografia do cálculo; para recalcular use a aba Todas.
A4: # | B4: Ordem geral | C4: Atividade (link no ClickUp) | D4: Processo | E4: Responsável principal | F4: Status no ClickUp | G4: Situação | H4: Natureza | I4: Nota final | J4: Cat. pela nota | K4: Veto aplicado? | L4: Risco | M4: Fin. | N4: Obra | O4: Legal | P4: Dep. | Q4: Esforço | R4: Por que entrou aqui
A5: 1 | B5: 57 | C5: Validar vínculo do adiantamento com Contas a Pagar do Pedido de Compra e no AR (tem que aparecer no Financeiro) | D5: Financeiro | E5: Alexandre Marchiori Cruz | F5: sem prazo definido | G5: Aberta | H5: Controle | I5: 3.87 | J5: 3 | L5: 5 | M5: 4 | N5: 1 | O5: 3 | P5: 3 | Q5: 3 | R5: risco de fraude/erro 5; impacto financeiro 4. é controle (+0,3).
A6: 2 | B6: 58 | C6: NFs de PJ não são lançadas no sistema - Ação: Definir regras contábeis e fiscais para o RH realizar o lançamento contábil das notas | D6: Financeiro | E6: Paulo Tavares | F6: em atraso | G6: Aberta | H6: Controle | I6: 3.87 | J6: 3 | L6: 4 | M6: 4 | N6: 1 | O6: 5 | P6: 3 | Q6: 3 | R6: exigência legal/CEF 5; risco de fraude/erro 4; impacto financeiro 4. é controle (+0,3).
A7: 3 | B7: 59 | C7: Elaborar POP - Processo de elaboração das viabilidades (Gadens e Make It | D7: Engenharia | E7: Eduardo Rosa | F7: em atraso | G7: Aberta | H7: Documento normativo | I7: 3.85 | J7: 3 | L7: 3 | M7: 5 | N7: 3 | O7: 3 | P7: 4 | Q7: 4 | R7: impacto financeiro 5; dependência 4.
A8: 4 | B8: 60 | C8: Padronização da EAP entre Orçamento e Planejamento (integração Prevision x Mega) | D8: Engenharia | E8: Hellen Venturoso | F8: em progresso | G8: Aberta | H8: Automação ou sistema | I8: 3.85 | J8: 3 | L8: 3 | M8: 4 | N8: 4 | O8: 2 | P8: 5 | Q8: 4 | R8: dependência 5; obra e entrega 4; impacto financeiro 4.
A9: 5 | B9: 62 | C9: Integração Prevision e Mega // Avaliar EAP de planejamento e orçamento na integração do Mega (Estudo de upload das views do Prevision para o Mega) com automatização da ponderação (pesos) na integração. Padronizar EAP entre orçamento e Planejamento | D9: Engenharia | E9: Alexandre Marchiori Cruz | F9: em progresso | G9: Aberta | H9: Automação ou sistema | I9: 3.85 | J9: 3 | L9: 3 | M9: 4 | N9: 4 | O9: 2 | P9: 5 | Q9: 5 | R9: dependência 5; obra e entrega 4; impacto financeiro 4.
A10: 6 | B10: 63 | C10: Avaliar a possibilidade de criar uma central de legalização | D10: Incorporação Make It | E10: Paula de Mattos Ribeiro | F10: pausado | G10: Aberta | H10: Definição ou decisão | I10: 3.85 | J10: 3 | L10: 3 | M10: 3 | N10: 4 | O10: 4 | P10: 4 | Q10: 5 | R10: obra e entrega 4; exigência legal/CEF 4; dependência 4.
A11: 7 | B11: 64 | C11: Avaliar a possibilidade de criar uma central de legalização | D11: Incorporação Gadens | E11: Mariane Cristine Machado Scandelari | F11: pausado | G11: Aberta | H11: Definição ou decisão | I11: 3.85 | J11: 3 | L11: 3 | M11: 3 | N11: 4 | O11: 4 | P11: 4 | Q11: 5 | R11: obra e entrega 4; exigência legal/CEF 4; dependência 4.
A12: 8 | B12: 67 | C12: Validação do cadastro do agente do empreiteiro (regime tributário do empreiteiro) | D12: GMO | E12: Grazielle de Oliveira | F12: em progresso | G12: Aberta | H12: Controle | I12: 3.82 | J12: 3 | L12: 4 | M12: 4 | N12: 1 | O12: 5 | P12: 3 | Q12: 3 | R12: exigência legal/CEF 5; risco de fraude/erro 4; impacto financeiro 4. é controle (+0,3).
A13: 9 | B13: 68 | C13: Criar fluxo de envio de contratos ao time de Segurança do Trabalho para conhecimento e plano de impedimento de acesso a obra em caso de divergências | D13: GMO | E13: Alessandro Braz | F13: em progresso | G13: Aberta | H13: Controle | I13: 3.82 | J13: 3 | L13: 4 | M13: 2 | N13: 3 | O13: 5 | P13: 3 | Q13: 3 | R13: exigência legal/CEF 5; risco de fraude/erro 4. é controle (+0,3).
A14: 10 | B14: 70 | C14: Estabelecer controles para garantir o cumprimento da Política Comercial do Empreendimento | D14: Comercial Make It | E14: André Garcia Vilas Boas | F14: pausado | G14: Aberta | H14: Controle | I14: 3.82 | J14: 3 | L14: 5 | M14: 4 | N14: 1 | O14: 3 | P14: 3 | Q14: 4 | R14: risco de fraude/erro 5; impacto financeiro 4. é controle (+0,3).
A15: 11 | B15: 71 | C15: Implementar sistema de Due Diligence // Definir critérios de compliance (due diligence) para fornecedores // Avaliar Due Diligence para Fornecedores | D15: GMO | E15: Edgard Machado Ferreira Junior | F15: em progresso | G15: Aberta | H15: Controle | I15: 3.82 | J15: 3 | L15: 4 | M15: 3 | N15: 2 | O15: 5 | P15: 3 | Q15: 5 | R15: exigência legal/CEF 5; risco de fraude/erro 4. é controle (+0,3).
A16: 12 | B16: 72 | C16: Criar fluxo de análise de consumo, considerando estoques, responsabilidade da baixa | D16: Engenharia | E16: Alessandro Braz | F16: sem prazo definido | G16: Aberta | H16: Definição ou decisão | I16: 3.79 | J16: 3 | L16: 4 | M16: 4 | N16: 3 | O16: 2 | P16: 4 | Q16: 3 | R16: risco de fraude/erro 4; impacto financeiro 4; dependência 4.
... A170: 166 | B170: 218 | C170: Revisão - importação do orçamento (perda de pacote) Problema: Falta de integração entre os sistemas Maxor e Mega Sugestão de melhoria: Integração Maxor x Mega | D170: Engenharia | E170: Leticia Gonçalves Bacchi | F170: cancelado | G170: Cancelada | H170: Automação ou sistema | I170: 3.31 | J170: 3 | L170: 3 | M170: 4 | N170: 3 | O170: 1 | P170: 4 | Q170: 4 | R170: impacto financeiro 4; dependência 4.

Sheet Todas
A1: Todas as atividades do ClickUp com a prioridade sugerida
A2: Leitura do ClickUp em 27/10/2026 (todos os status). A prioridade que já estava no ClickUp não foi usada. Notas manuais e regra base são proposta minha; células amarelas podem ser editadas.
A4: Ordem geral | B4: ID | C4: Atividade (link no ClickUp) | D4: Processo | E4: Responsável principal | F4: Todos os responsáveis | G4: Status no ClickUp | H4: Situação | I4: Natureza | J4: Esforço (1–5) | K4: Risco de fraude e erro | L4: Impacto financeiro | M4: Obra e entrega | N4: Legal, CEF e compliance | O4: Dependência | P4: Para obra ou repasse CEF? | Q4: Origem da nota | R4: Média ponderada | S4: Fator do processo | T4: Ajuste da natureza | U4: Nota final | V4: Cat. pela nota | W4: Cat. final | X4: Prioridade sugerida | Y4: Chave | Z4: Por que
A5: =IF(Y5="","",COUNTIF($Y$5:$Y$983,">"&Y5)+1) -> 1 | B5: 86acvyn3f | C5: Estruturar e aprovar Plano de Alçadas formal para aprovações de compras e contratações | D5: Novos Negócios | E5: (sem responsável) | F5: (sem responsável) | G5: concluído | H5: Concluída | I5: Controle | J5: 4 | K5: 5 | L5: 5 | M5: 3 | N5: 3 | O5: 5 | P5: Não | Q5: Manual (proposta) | R5: =ROUND((K5*Parametros!$B$4+L5*Parametros!$B$5+M5*Parametros!$B$6+N5*Parametros!$B$7+O5*Parametros!$B$8)/SUM(Parametros!$B$4:$B$8),2) -> 4.3 | S5: =IFERROR(INDEX(Parametros!$F$33:$F$42,MATCH(D5,Parametros!$A$33:$A$42,0)),1) -> 1.067 | T5: =IFERROR(INDEX(Parametros!$B$21:$B$26,MATCH(I5,Parametros!$A$21:$A$26,0)),0) -> 0.3 | U5: =ROUND(R5*S5+T5,2) -> 4.89 | V5: =IF(U5>=Parametros!$B$14,4,IF(U5>=Parametros!$B$13,3,IF(U5>=Parametros!$B$12,2,1))) -> 4 | W5: =MAX(V5,IF(K5=5,Parametros!$B$17,0),IF(P5="Sim",Parametros!$B$18,0)) -> 4 | X5: =CHOOSE(W5,"Baixa","Normal","Alta","Urgente") -> Urgente | Y5: =W5*1000+U5*10-J5/10-ROW()/1000000 -> 4048.5 | Z5: risco de fraude/erro 5; impacto financeiro 5; dependência 5. é controle (+0,3).
A6: =IF(Y6="","",COUNTIF($Y$5:$Y$983,">"&Y6)+1) -> 2 | B6: 86acmweg8 | C6: Estruturar e aprovar Plano de Alçadas formal para aprovações de compras e contratações e disponibilizar em manual corporativo. (Falta de definição de plano de alçadas e autonomia.) | D6: Novos Negócios | E6: Bruna Oliveira Ribeiro | F6: Bruna Oliveira Ribeiro | G6: em atraso | H6: Aberta | I6: Controle | J6: 4 | K6: 5 | L6: 5 | M6: 3 | N6: 3 | O6: 5 | P6: Não | Q6: Manual (proposta) | R6: =ROUND((K6*Parametros!$B$4+L6*Parametros!$B$5+M6*Parametros!$B$6+N6*Parametros!$B$7+O6*Parametros!$B$8)/SUM(Parametros!$B$4:$B$8),2) -> 4.3 | S6: =IFERROR(INDEX(Parametros!$F$33:$F$42,MATCH(D6,Parametros!$A$33:$A$42,0)),1) -> 1.067 | T6: =IFERROR(INDEX(Parametros!$B$21:$B$26,MATCH(I6,Parametros!$A$21:$A$26,0)),0) -> 0.3 | U6: =ROUND(R6*S6+T6,2) -> 4.89 | V6: =IF(U6>=Parametros!$B$14,4,IF(U6>=Parametros!$B$13,3,IF(U6>=Parametros!$B$12,2,1))) -> 4 | W6: =MAX(V6,IF(K6=5,Parametros!$B$17,0),IF(P6="Sim",Parametros!$B$18,0)) -> 4 | X6: =CHOOSE(W6,"Baixa","Normal","Alta","Urgente") -> Urgente | Y6: =W6*1000+U6*10-J6/10-ROW()/1000000 -> 4048.5 | Z6: risco de fraude/erro 5; impacto financeiro 5; dependência 5. é controle (+0,3).
A7: =IF(Y7="","",COUNTIF($Y$5:$Y$983,">"&Y7)+1) -> 3 | B7: 86akm8zdk | C7: Definir alçada de assinaturas para contratação de mão de obra (Política de Contratos) | D7: GMO | E7: Bruna Oliveira Ribeiro | F7: Bruna Oliveira Ribeiro | G7: em progresso | H7: Aberta | I7: Controle | J7: 3 | K7: 5 | L7: 4 | M7: 3 | N7: 4 | O7: 5 | P7: Não | Q7: Manual (proposta) | R7: =ROUND((K7*Parametros!$B$4+L7*Parametros!$B$5+M7*Parametros!$B$6+N7*Parametros!$B$7+O7*Parametros!$B$8)/SUM(Parametros!$B$4:$B$8),2) -> 4.25 | S7: =IFERROR(INDEX(Parametros!$F$33:$F$42,MATCH(D7,Parametros!$A$33:$A$42,0)),1) -> 1.034 | T7: =IFERROR(INDEX(Parametros!$B$21:$B$26,MATCH(I7,Parametros!$A$21:$A$26,0)),0) -> 0.3 | U7: =ROUND(R7*S7+T7,2) -> 4.69 | V7: =IF(U7>=Parametros!$B$14,4,IF(U7>=Parametros!$B$13,3,IF(U7>=Parametros!$B$12,2,1))) -> 4 | W7: =MAX(V7,IF(K7=5,Parametros!$B$17,0),IF(P7="Sim",Parametros!$B$18,0)) -> 4 | X7: =CHOOSE(W7,"Baixa","Normal","Alta","Urgente") -> Urgente | Y7: =W7*1000+U7*10-J7/10-ROW()/1000000 -> 4046.6 | Z7: risco de fraude/erro 5; dependência 5; impacto financeiro 4; exigência legal/CEF 4. é controle (+0,3).
A8: =IF(Y8="","",COUNTIF($Y$5:$Y$983,">"&Y8)+1) -> 4 | B8: 86aghrguf | C8: Serviço iniciado pela Obra sem contrato assinado | D8: GMO | E8: Lizandra de Liz | F8: Lizandra de Liz | G8: concluído | H8: Concluída | I8: Controle | J8: 3 | K8: 5 | L8: 4 | M8: 4 | N8: 4 | O8: 3 | P8: Não | Q8: Manual (proposta) | R8: =ROUND((K8*Parametros!$B$4+L8*Parametros!$B$5+M8*Parametros!$B$6+N8*Parametros!$B$7+O8*Parametros!$B$8)/SUM(Parametros!$B$4:$B$8),2) -> 4.15 | S8: =IFERROR(INDEX(Parametros!$F$33:$F$42,MATCH(D8,Parametros!$A$33:$A$42,0)),1) -> 1.034 | T8: =IFERROR(INDEX(Parametros!$B$21:$B$26,MATCH(I8,Parametros!$A$21:$A$26,0)),0) -> 0.3 | U8: =ROUND(R8*S8+T8,2) -> 4.59 | V8: =IF(U8>=Parametros!$B$14,4,IF(U8>=Parametros!$B$13,3,IF(U8>=Parametros!$B$12,2,1))) -> 4 | W8: =MAX(V8,IF(K8=5,Parametros!$B$17,0),IF(P8="Sim",Parametros!$B$18,0)) -> 4 | X8: =CHOOSE(W8,"Baixa","Normal","Alta","Urgente") -> Urgente | Y8: =W8*1000+U8*10-J8/10-ROW()/1000000 -> 4045.6 | Z8: risco de fraude/erro 5; obra e entrega 4; impacto financeiro 4; exigência legal/CEF 4. é controle (+0,3).
A9: =IF(Y9="","",COUNTIF($Y$5:$Y$983,">"&Y9)+1) -> 5 | B9: 86akm8zd0 | C9: Definir fluxo de aprovação de contratos de empreiteiros | D9: GMO | E9: Bruna Oliveira Ribeiro | F9: Bruna Oliveira Ribeiro | G9: em progresso | H9: Aberta | I9: Controle | J9: 3 | K9: 4 | L9: 4 | M9: 4 | N9: 4 | O9: 4 | P9: Não | Q9: Manual (proposta) | R9: =ROUND((K9*Parametros!$B$4+L9*Parametros!$B$5+M9*Parametros!$B$6+N9*Parametros!$B$7+O9*Parametros!$B$8)/SUM(Parametros!$B$4:$B$8),2) -> 4 | S9: =IFERROR(INDEX(Parametros!$F$33:$F$42,MATCH(D9,Parametros!$A$33:$A$42,0)),1) -> 1.034 | T9: =IFERROR(INDEX(Parametros!$B$21:$B$26,MATCH(I9,Parametros!$A$21:$A$26,0)),0) -> 0.3 | U9: =ROUND(R9*S9+T9,2) -> 4.44 | V9: =IF(U9>=Parametros!$B$14,4,IF(U9>=Parametros!$B$13,3,IF(U9>=Parametros!$B$12,2,1))) -> 4 | W9: =MAX(V9,IF(K9=5,Parametros!$B$17,0),IF(P9="Sim",Parametros!$B$18,0)) -> 4 | X9: =CHOOSE(W9,"Baixa","Normal","Alta","Urgente") -> Urgente | Y9: =W9*1000+U9*10-J9/10-ROW()/1000000 -> 4044.1 | Z9: risco de fraude/erro 4; obra e entrega 4; impacto financeiro 4; exigência legal/CEF 4; dependência 4. é controle (+0,3).
A10: =IF(Y10="","",COUNTIF($Y$5:$Y$983,">"&Y10)+1) -> 6 | B10: 86aghkwdz | C10: Definir regra de perfis de acesso / Revisão dos acessos (colaboradores transferidos de empresa área, desligados etc.) | D10: Financeiro | E10: Roberto Dias | F10: Roberto Dias | G10: em atraso | H10: Aberta | I10: Controle | J10: 3 | K10: 5 | L10: 4 | M10: 2 | N10: 4 | O10: 4 | P10: Não | Q10: Manual (proposta) | R10: =ROUND((K10*Parametros!$B$4+L10*Parametros!$B$5+M10*Parametros!$B$6+N10*Parametros!$B$7+O10*Parametros!$B$8)/SUM(Parametros!$B$4:$B$8),2) -> 3.9 | S10: =IFERROR(INDEX(Parametros!$F$33:$F$42,MATCH(D10,Parametros!$A$33:$A$42,0)),1) -> 1.05 | T10: =IFERROR(INDEX(Parametros!$B$21:$B$26,MATCH(I10,Parametros!$A$21:$A$26,0)),0) -> 0.3 | U10: =ROUND(R10*S10+T10,2) -> 4.4 | V10: =IF(U10>=Parametros!$B$14,4,IF(U10>=Parametros!$B$13,3,IF(U10>=Parametros!$B$12,2,1))) -> 4 | W10: =MAX(V10,IF(K10=5,Parametros!$B$17,0),IF(P10="Sim",Parametros!$B$18,0)) -> 4 | X10: =CHOOSE(W10,"Baixa","Normal","Alta","Urgente") -> Urgente | Y10: =W10*1000+U10*10-J10/10-ROW()/1000000 -> 4043.7 | Z10: risco de fraude/erro 5; impacto financeiro 4; exigência legal/CEF 4; dependência 4. é controle (+0,3).
A11: =IF(Y11="","",COUNTIF($Y$5:$Y$983,">"&Y11)+1) -> 7 | B11: 86aget7z8 | C11: Travas sistêmicas no input da nota fiscal no sistema / recebimento físico / fiscal (pedido, quantidade, preço, fornecedor etc.) | D11: Suprimentos | E11: Cleber Colin | F11: Cleber Colin | G11: concluído | H11: Concluída | I11: Controle | J11: 5 | K11: 5 | L11: 4 | M11: 2 | N11: 4 | O11: 4 | P11: Não | Q11: Manual (proposta) | R11: =ROUND((K11*Parametros!$B$4+L11*Parametros!$B$5+M11*Parametros!$B$6+N11*Parametros!$B$7+O11*Parametros!$B$8)/SUM(Parametros!$B$4:$B$8),2) -> 3.9 | S11: =IFERROR(INDEX(Parametros!$F$33:$F$42,MATCH(D11,Parametros!$A$33:$A$42,0)),1) -> 1.05 | T11: =IFERROR(INDEX(Parametros!$B$21:$B$26,MATCH(I11,Parametros!$A$21:$A$26,0)),0) -> 0.3 | U11: =ROUND(R11*S11+T11,2) -> 4.4 | V11: =IF(U11>=Parametros!$B$14,4,IF(U11>=Parametros!$B$13,3,IF(U11>=Parametros!$B$12,2,1))) -> 4 | W11: =MAX(V11,IF(K11=5,Parametros!$B$17,0),IF(P11="Sim",Parametros!$B$18,0)) -> 4 | X11: =CHOOSE(W11,"Baixa","Normal","Alta","Urgente") -> Urgente | Y11: =W11*1000+U11*10-J11/10-ROW()/1000000 -> 4043.5 | Z11: risco de fraude/erro 5; impacto financeiro 4; exigência legal/CEF 4; dependência 4. é controle (+0,3).
A12: =IF(Y12="","",COUNTIF($Y$5:$Y$983,">"&Y12)+1) -> 8 | B12: 86aj81736 | C12: Implementar Indicador - Avanço físico versus avanço financeiro (medição) | D12: Engenharia | E12: Hellen Venturoso | F12: Hellen Venturoso | G12: pausado | H12: Aberta | I12: Controle | J12: 3 | K12: 4 | L12: 5 | M12: 4 | N12: 2 | O12: 3 | P12: Não | Q12: Manual (proposta) | R12: =ROUND((K12*Parametros!$B$4+L12*Parametros!$B$5+M12*Parametros!$B$6+N12*Parametros!$B$7+O12*Parametros!$B$8)/SUM(Parametros!$B$4:$B$8),2) -> 3.75 | S12: =IFERROR(INDEX(Parametros!$F$33:$F$42,MATCH(D12,Parametros!$A$33:$A$42,0)),1) -> 1.084 | T12: =IFERROR(INDEX(Parametros!$B$21:$B$26,MATCH(I12,Parametros!$A$21:$A$26,0)),0) -> 0.3 | U12: =ROUND(R12*S12+T12,2) -> 4.37 | V12: =IF(U12>=Parametros!$B$14,4,IF(U12>=Parametros!$B$13,3,IF(U12>=Parametros!$B$12,2,1))) -> 4 | W12: =MAX(V12,IF(K12=5,Parametros!$B$17,0),IF(P12="Sim",Parametros!$B$18,0)) -> 4 | X12: =CHOOSE(W12,"Baixa","Normal","Alta","Urgente") -> Urgente | Y12: =W12*1000+U12*10-J12/10-ROW()/1000000 -> 4043.4 | Z12: impacto financeiro 5; risco de fraude/erro 4; obra e entrega 4. é controle (+0,3).
A13: =IF(Y13="","",COUNTIF($Y$5:$Y$983,">"&Y13)+1) -> 9 | B13: 86agetqqx | C13: Elaborar Política - Política de compras e contratação de fornecedores, contemplando critérios de aquisição de materiais e serviços, regras de utilização entre pedido de compra e cartão corporativo, fluxo de compras emergenciais, homologação de fornecedores, alçadas, responsabilidades e controles aplicáveis ao processo. | D13: Suprimentos | E13: Cleber Colin | F13: Cleber Colin | G13: em atraso | H13: Aberta | I13: Documento normativo | J13: 4 | K13: 4 | L13: 5 | M13: 3 | N13: 4 | O13: 5 | P13: Não | Q13: Manual (proposta) | R13: =ROUND((K13*Parametros!$B$4+L13*Parametros!$B$5+M13*Parametros!$B$6+N13*Parametros!$B$7+O13*Parametros!$B$8)/SUM(Parametros!$B$4:$B$8),2) -> 4.15 | S13: =IFERROR(INDEX(Parametros!$F$33:$F$42,MATCH(D13,Parametros!$A$33:$A$42,0)),1) -> 1.05 | T13: =IFERROR(INDEX(Parametros!$B$21:$B$26,MATCH(I13,Parametros!$A$21:$A$26,0)),0) -> 0 | U13: =ROUND(R13*S13+T13,2) -> 4.36 | V13: =IF(U13>=Parametros!$B$14,4,IF(U13>=Parametros!$B$13,3,IF(U13>=Parametros!$B$12,2,1))) -> 4 | W13: =MAX(V13,IF(K13=5,Parametros!$B$17,0),IF(P13="Sim",Parametros!$B$18,0)) -> 4 | X13: =CHOOSE(W13,"Baixa","Normal","Alta","Urgente") -> Urgente | Y13: =W13*1000+U13*10-J13/10-ROW()/1000000 -> 4043.2 | Z13: impacto financeiro 5; dependência 5; risco de fraude/erro 4; exigência legal/CEF 4.
A14: =IF(Y14="","",COUNTIF($Y$5:$Y$983,">"&Y14)+1) -> 10 | B14: 86ahckp0b | C14: Elaborar POP - Procedimento de interrupção de obra por motivos de segurança POP | D14: Engenharia | E14: Alessandro Braz | F14: Alessandro Braz | G14: em atraso | H14: Aberta | I14: Documento normativo | J14: 3 | K14: 4 | L14: 3 | M14: 5 | N14: 5 | O14: 3 | P14: Não | Q14: Manual (proposta) | R14: =ROUND((K14*Parametros!$B$4+L14*Parametros!$B$5+M14*Parametros!$B$6+N14*Parametros!$B$7+O14*Parametros!$B$8)/SUM(Parametros!$B$4:$B$8),2) -> 4 | S14: =IFERROR(INDEX(Parametros!$F$33:$F$42,MATCH(D14,Parametros!$A$33:$A$42,0)),1) -> 1.084 | T14: =IFERROR(INDEX(Parametros!$B$21:$B$26,MATCH(I14,Parametros!$A$21:$A$26,0)),0) -> 0 | U14: =ROUND(R14*S14+T14,2) -> 4.34 | V14: =IF(U14>=Parametros!$B$14,4,IF(U14>=Parametros!$B$13,3,IF(U14>=Parametros!$B$12,2,1))) -> 4 | W14: =MAX(V14,IF(K14=5,Parametros!$B$17,0),IF(P14="Sim",Parametros!$B$18,0)) -> 4 | X14: =CHOOSE(W14,"Baixa","Normal","Alta","Urgente") -> Urgente | Y14: =W14*1000+U14*10-J14/10-ROW()/1000000 -> 4043.1 | Z14: obra e entrega 5; exigência legal/CEF 5; risco de fraude/erro 4.
A15: =IF(Y15="","",COUNTIF($Y$5:$Y$983,">"&Y15)+1) -> 11 | B15: 86agjaf19 | C15: Aplicar as penalidades contempladas em contrato com a empreiteira/construtora quando do não cumprimento dos itens apontados na vistoria (Andressa / Apoio Alessandro e Hellen)" | D15: Engenharia | E15: Edgard Machado Ferreira Junior | F15: Edgard Machado Ferreira Junior, Andressa Gazolla Gutmann | G15: em atraso | H15: Aberta | I15: Controle | J15: 2 | K15: 4 | L15: 4 | M15: 4 | N15: 4 | O15: 2 | P15: Não | Q15: Manual (proposta) | R15: =ROUND((K15*Parametros!$B$4+L15*Parametros!$B$5+M15*Parametros!$B$6+N15*Parametros!$B$7+O15*Parametros!$B$8)/SUM(Parametros!$B$4:$B$8),2) -> 3.7 | S15: =IFERROR(INDEX(Parametros!$F$33:$F$42,MATCH(D15,Parametros!$A$33:$A$42,0)),1) -> 1.084 | T15: =IFERROR(INDEX(Parametros!$B$21:$B$26,MATCH(I15,Parametros!$A$21:$A$26,0)),0) -> 0.3 | U15: =ROUND(R15*S15+T15,2) -> 4.31 | V15: =IF(U15>=Parametros!$B$14,4,IF(U15>=Parametros!$B$13,3,IF(U15>=Parametros!$B$12,2,1))) -> 4 | W15: =MAX(V15,IF(K15=5,Parametros!$B$17,0),IF(P15="Sim",Parametros!$B$18,0)) -> 4 | X15: =CHOOSE(W15,"Baixa","Normal","Alta","Urgente") -> Urgente | Y15: =W15*1000+U15*10-J15/10-ROW()/1000000 -> 4042.9 | Z15: risco de fraude/erro 4; obra e entrega 4; impacto financeiro 4; exigência legal/CEF 4. é controle (+0,3).
A16: =IF(Y16="","",COUNTIF($Y$5:$Y$983,">"&Y16)+1) -> 12 | B16: 86ahcknyj | C16: Avaliar relatório de revisão de desembolso obra | D16: Engenharia | E16: Cleverton Parnoff | F16: Cleverton Parnoff | G16: em progresso | H16: Aberta | I16: Controle | J16: 3 | K16: 4 | L16: 5 | M16: 3 | N16: 3 | O16: 3 | P16: Não | Q16: Manual (proposta) | R16: =ROUND((K16*Parametros!$B$4+L16*Parametros!$B$5+M16*Parametros!$B$6+N16*Parametros!$B$7+O16*Parametros!$B$8)/SUM(Parametros!$B$4:$B$8),2) -> 3.7 | S16: =IFERROR(INDEX(Parametros!$F$33:$F$42,MATCH(D16,Parametros!$A$33:$A$42,0)),1) -> 1.084 | T16: =IFERROR(INDEX(Parametros!$B$21:$B$26,MATCH(I16,Parametros!$A$21:$A$26,0)),0) -> 0.3 | U16: =ROUND(R16*S16+T16,2) -> 4.31 | V16: =IF(U16>=Parametros!$B$14,4,IF(U16>=Parametros!$B$13,3,IF(U16>=Parametros!$B$12,2,1))) -> 4 | W16: =MAX(V16,IF(K16=5,Parametros!$B$17,0),IF(P16="Sim",Parametros!$B$18,0)) -> 4 | X16: =CHOOSE(W16,"Baixa","Normal","Alta","Urgente") -> Urgente | Y16: =W16*1000+U16*10-J16/10-ROW()/1000000 -> 4042.8 | Z16: impacto financeiro 5; risco de fraude/erro 4. é controle (+0,3).
... A983: =IF(Y983="","",COUNTIF($Y$5:$Y$983,">"&Y983)+1) -> 979 | B983: 17tpepcdk0n | C983: Implantar pesquisa NPS sobre o treinamento das imobiliárias | D983: Comercial Gadens | E983: Mônica Massaneiro | F983: Mônica Massaneiro | G983: em progresso | H983: Aberta | I983: Indicador | J983: 2 | K983: 1 | L983: 1 | M983: 1 | N983: 1 | O983: 1 | P983: Não | Q983: Manual (proposta) | R983: =ROUND((K983*Parametros!$B$4+L983*Parametros!$B$5+M983*Parametros!$B$6+N983*Parametros!$B$7+O983*Parametros!$B$8)/SUM(Parametros!$B$4:$B$8),2) -> 1 | S983: =IFERROR(INDEX(Parametros!$F$33:$F$42,MATCH(D983,Parametros!$A$33:$A$42,0)),1) -> 1.017 | T983: =IFERROR(INDEX(Parametros!$B$21:$B$26,MATCH(I983,Parametros!$A$21:$A$26,0)),0) -> -0.3 | U983: =ROUND(R983*S983+T983,2) -> 0.72 | V983: =IF(U983>=Parametros!$B$14,4,IF(U983>=Parametros!$B$13,3,IF(U983>=Parametros!$B$12,2,1))) -> 1 | W983: =MAX(V983,IF(K983=5,Parametros!$B$17,0),IF(P983="Sim",Parametros!$B$18,0)) -> 1 | X983: =CHOOSE(W983,"Baixa","Normal","Alta","Urgente") -> Baixa | Y983: =W983*1000+U983*10-J983/10-ROW()/1000000 -> 1006.999 | Z983: nenhum critério com nota 4 ou 5. indicador (-0,3).

Sheet Parametros
A1: Parâmetros da matriz
A2: Células azuis em fundo amarelo podem ser editadas; a aba Todas recalcula. As abas Urgente e Alta são uma fotografia do cálculo na data de geração.
A3: Critério | B3: Peso (%)
A4: Risco de fraude e erro | B4: 30
A5: Impacto financeiro | B5: 20
A6: Impacto na obra e na entrega | B6: 20
A7: Exigência legal, CEF e compliance | B7: 15
A8: Dependência | B8: 15
A9: Soma dos pesos | B9: =SUM(B4:B8) -> 100 | C9: =IF(B9=100,"ok","os pesos devem somar 100") -> ok
A11: Cortes das categorias (nota mínima)
A12: 2 · Normal (≥) | B12: 2.5
A13: 3 · Alta (≥) | B13: 3.3
A14: 4 · Urgente (≥) | B14: 3.9 | C14: O corte proposto antes era 4,0. Com ele, Urgente ficava em 4,2% do total, abaixo da faixa mínima de 5%. Baixei para 3,9.
A16: Regras que passam por cima da conta (categoria mínima)
A17: Risco = 5 | B17: 3
A18: Para obra ou repasse da CEF = Sim | B18: 4
A20: Ajuste por natureza (somado à nota)
A21: Controle | B21: 0.3
A22: Documento normativo | B22: 0
A23: Automação ou sistema | B23: 0
A24: Definição ou decisão | B24: 0
A25: Treinamento | B25: -0.2
A26: Indicador | B26: -0.3
A28: Fator do processo
A29: Fator mínimo | B29: 0.9
A30: Fator máximo | B30: 1.1
A32: Processo | B32: Dinheiro | C32: Dependência | D32: Irreversibilidade | E32: Média | F32: Fator
A33: Incorporação Make It | B33: 5 | C33: 5 | D33: 5 | E33: =ROUND(AVERAGE(B33:D33),2) -> 5 | F33: =ROUND($B$29+($B$30-$B$29)*(E33-1)/4,3) -> 1.1
A34: Incorporação Gadens | B34: 5 | C34: 5 | D34: 5 | E34: =ROUND(AVERAGE(B34:D34),2) -> 5 | F34: =ROUND($B$29+($B$30-$B$29)*(E34-1)/4,3) -> 1.1
A35: Engenharia | B35: 5 | C35: 5 | D35: 4 | E35: =ROUND(AVERAGE(B35:D35),2) -> 4.67 | F35: =ROUND($B$29+($B$30-$B$29)*(E35-1)/4,3) -> 1.084
A36: Novos Negócios | B36: 5 | C36: 3 | D36: 5 | E36: =ROUND(AVERAGE(B36:D36),2) -> 4.33 | F36: =ROUND($B$29+($B$30-$B$29)*(E36-1)/4,3) -> 1.067
A37: Suprimentos | B37: 5 | C37: 4 | D37: 3 | E37: =ROUND(AVERAGE(B37:D37),2) -> 4 | F37: =ROUND($B$29+($B$30-$B$29)*(E37-1)/4,3) -> 1.05
A38: Financeiro | B38: 4 | C38: 5 | D38: 3 | E38: =ROUND(AVERAGE(B38:D38),2) -> 4 | F38: =ROUND($B$29+($B$30-$B$29)*(E38-1)/4,3) -> 1.05
A39: GMO | B39: 4 | C39: 4 | D39: 3 | E39: =ROUND(AVERAGE(B39:D39),2) -> 3.67 | F39: =ROUND($B$29+($B$30-$B$29)*(E39-1)/4,3) -> 1.034
A40: Comercial Make It | B40: 4 | C40: 4 | D40: 3 | E40: =ROUND(AVERAGE(B40:D40),2) -> 3.67 | F40: =ROUND($B$29+($B$30-$B$29)*(E40-1)/4,3) -> 1.034
A41: Comercial Gadens | B41: 4 | C41: 3 | D41: 3 | E41: =ROUND(AVERAGE(B41:D41),2) -> 3.33 | F41: =ROUND($B$29+($B$30-$B$29)*(E41-1)/4,3) -> 1.017
A42: Sem processo definido | B42: 3 | C42: 3 | D42: 3 | E42: =ROUND(AVERAGE(B42:D42),2) -> 3 | F42: =ROUND($B$29+($B$30-$B$29)*(E42-1)/4,3) -> 1
